Workbook
Name 年计划量: #REF!
Name 日计划: #REF!
Name 日销售量: 日销售量!$1:$1048576
Name 月销售量: #REF!
Name 月销售量: #REF!
Name 月销售量: #REF!

Sheet ICLPTOVOVTNRYY
B1: 77 83 67 70 0 0 0 0 157 27 1 0 0 0 0 0 48 24 0 0 0 0 0 0 3 1 1 0 5 0 4 0 247 20 0 0 0 24 0 0 0 0 0 0 0 0 0 0 0 0 0 0 0 0 0 0 0 0 0 0 0 0 0 0 0 0 0 0 0 0 0 0 0 0 0 0 0 0 0 0 0 0 0 0 0 0 0 0 0 0 0 0 0 0 0 0 0 0 0 0 0 0 0 0 0 0 0 0 0 0 0 0 0 0 0 0 0 0 0 0 0 0 0 0 0 0 0 0 0 0 0 0 0 0 0 0 0 0 0 0 0 0 0 0 0 0 0 0 0 0 0 0 0 0 0 0 0 0 0 0 0 0 0 0 0 0 0 0 0 0 0 0 0 0 0 0 0 0 0 0 0 0 0 0 0 0 0 0 0 0 0 0 0 0 0 0 0 0 0 0 0 0 0 0 0 0 0 0 0 0 0 0 0 0 0 0 0 0 0 0 0 0 0 0 0 0 0 0 0 0 0 0 0 0 0 0 0 0 0 0 0 0 0 0 0 0 0 0 0 0 0 0 0 0 0 0 0 0 0 0 0 0 0 0 0 0 0 0 0 0 0 0 0 0 0 0 0 0 0 0 0 0 0 0 0 0 0 0 0 0 0 0 0 0 0 0 0 0 0 0 0 0 0 0 0 0 0 0 0 0 0 0 0 0 0 0 0 0 0 0 0 0 0 0 0 0 0 0 0 0 0 0 0 0 0 0 0 0 0 0 0 0 0 0 0 0 0 0 0 0 0 0 0 0 0 0 0 0 0 0 0 0 0 0 0 0 0 0 0 0 0 0 0 0 0 0 0 0 0 0 0 0 0 0 0 0 0 0 0 0 0 0 0 0 0 0 0 0 0 0 0 0 0 0 0 0 0 0 0 0 0 0 0 0 0 0 0 0 0 0 0 0 0 0 0 0 0 0 0 0 0 0 0 0 0 0 0 0 0 0 0 0 0 0 0 0 0 0 0 0 0 0 0 0 0 0 0 0 0 0 0 0 0 0 0 0 0 0 0 0 0 0 0 0 0 0 0 0 0 0 0 0 0 0 0 0 0 0 0 0 0 0 0 0 0 0 0 0 0 0 0 0 0 0 0 0 0 0 0 0 0 0 | C1: Private Sub createcabfile()
B2: 0 0 0 0 0 0 0 0 0 0 0 0 0 0 0 0 0 0 0 0 0 0 0 0 0 0 0 0 0 0 0 0 0 0 0 0 0 0 0 0 0 0 0 0 0 0 0 0 0 0 0 0 0 0 0 0 0 0 0 0 0 0 0 0 0 0 0 0 0 0 0 0 0 0 0 0 0 0 0 0 0 0 0 0 0 0 0 0 0 0 0 0 0 0 0 0 0 0 0 0 0 0 0 0 0 0 0 0 0 0 0 0 0 0 0 0 0 0 0 0 0 0 0 0 0 0 0 0 0 0 0 0 0 0 0 0 0 0 0 0 0 0 0 0 0 0 0 0 0 0 0 0 0 0 0 0 0 0 0 0 0 0 0 0 0 0 0 0 0 0 0 0 0 0 0 0 0 0 0 0 0 0 0 0 0 0 0 0 0 0 0 0 0 0 0 0 0 0 0 0 0 0 0 0 0 0 0 0 0 0 0 0 0 0 0 0 0 0 0 0 0 0 0 0 0 0 0 0 0 0 0 0 0 0 0 0 0 0 0 0 0 0 0 0 0 0 0 0 0 0 0 0 0 0 0 0 0 0 0 0 0 0 0 0 0 0 0 0 0 0 0 0 0 0 0 0 0 0 0 0 0 0 0 0 0 0 0 0 0 0 0 0 0 0 0 0 0 0 0 0 0 0 0 0 0 0 0 0 0 0 0 0 0 0 0 0 0 0 0 0 0 0 0 0 0 0 0 0 0 0 0 0 0 0 0 0 0 0 0 0 0 0 0 0 0 0 0 0 0 0 0 0 0 0 0 0 0 0 0 0 0 0 0 0 0 0 0 0 0 0 0 0 0 0 0 0 0 0 0 0 0 0 0 0 0 0 0 0 0 0 0 0 0 0 0 0 0 0 0 0 0 0 0 0 0 0 0 0 0 0 0 0 0 0 0 0 0 0 0 0 0 0 0 0 0 0 0 0 0 0 0 0 0 0 0 0 0 0 0 0 0 0 0 0 0 0 0 0 0 0 0 0 0 0 0 0 0 0 0 0 0 0 0 0 0 0 0 0 0 0 0 0 0 0 0 0 0 0 0 0 0 0 0 0 0 0 0 0 0 0 0 0 0 0 0 0 0 0 0 0 0 0 0 0 0 0 0 0 0 0 0 0 | C2: Dim ch As Byte
B3: 0 0 0 0 0 0 0 0 0 0 0 0 0 0 0 0 0 0 0 0 0 0 0 0 0 0 0 0 0 0 0 0 0 0 0 0 0 0 0 0 0 0 0 0 0 0 0 0 0 0 0 0 0 0 0 0 0 0 0 0 0 0 0 0 0 0 0 0 0 0 0 0 0 0 0 0 0 0 0 0 0 0 0 0 0 0 0 0 0 0 0 0 0 0 0 0 0 0 0 0 0 0 0 0 0 0 0 0 0 0 0 0 0 0 0 0 0 0 0 0 0 0 0 0 0 0 0 0 0 0 0 0 0 0 0 0 0 0 0 0 0 0 0 0 0 0 0 0 0 0 0 0 0 0 0 0 0 0 0 0 0 0 0 0 0 0 0 0 0 0 0 0 0 0 0 0 0 0 0 0 0 0 0 0 0 0 0 0 0 0 0 0 0 0 0 0 0 0 0 0 0 0 0 0 0 0 0 0 0 0 0 0 0 0 0 0 0 0 0 0 0 0 0 0 0 0 0 0 0 0 0 0 0 0 0 0 0 0 0 0 0 0 0 0 0 0 0 0 0 0 0 0 0 0 0 0 0 0 0 0 0 0 0 0 0 0 0 0 0 0 0 0 0 0 0 0 0 0 0 0 0 0 0 0 0 0 0 0 0 0 0 0 0 0 0 0 0 0 0 0 0 0 0 0 0 0 0 0 0 0 0 0 0 0 0 0 0 0 0 0 0 0 0 0 0 0 0 0 0 0 0 0 0 0 0 0 0 0 0 0 0 0 0 0 0 0 0 0 0 0 0 0 0 0 0 0 0 0 0 0 0 0 0 0 0 0 0 0 0 0 0 0 0 0 0 0 0 0 0 0 0 0 0 0 0 0 0 0 0 0 0 0 0 0 0 0 0 0 0 0 0 0 0 0 0 0 0 0 0 0 0 0 0 0 0 0 0 0 0 0 0 0 0 0 0 0 0 0 0 0 0 0 0 0 0 0 0 0 0 0 0 0 0 0 0 0 0 0 0 0 0 0 0 0 0 0 0 0 0 0 0 0 0 0 0 0 0 0 0 0 0 0 0 0 0 0 0 0 0 0 0 0 0 0 0 0 0 0 0 0 0 0 0 0 0 0 0 0 0 0 0 0 0 0 0 0 0 0 0 0 0 0 | C3: on error resume next
B4: 0 0 0 0 0 0 0 0 0 0 0 0 0 0 0 0 0 0 0 0 0 0 0 0 0 0 0 0 0 0 0 0 0 0 0 0 0 0 0 0 0 0 0 0 0 0 0 0 0 0 0 0 0 0 0 0 0 0 0 0 0 0 0 0 0 0 0 0 0 0 0 0 0 0 0 0 0 0 0 0 0 0 0 0 0 0 0 0 0 0 0 0 0 0 0 0 0 0 0 0 0 0 0 0 0 0 0 0 0 0 0 0 0 0 0 0 0 0 0 0 0 0 0 0 0 0 0 0 0 0 0 0 0 0 0 0 0 0 0 0 0 0 0 0 0 0 0 0 0 0 0 0 0 0 0 0 0 0 0 0 0 0 0 0 0 0 0 0 0 0 0 0 0 0 0 0 0 0 0 0 0 0 0 0 0 0 0 0 0 0 0 0 0 0 0 0 0 0 0 0 0 0 0 0 0 0 0 0 0 0 0 0 0 0 0 0 0 0 0 0 0 0 0 0 0 0 0 0 0 0 0 0 0 0 0 0 0 0 0 0 0 0 0 0 0 0 0 0 0 0 0 0 0 0 0 0 0 0 0 0 0 0 0 0 0 0 0 0 0 0 0 0 0 0 0 0 0 0 0 0 0 0 0 0 0 0 0 0 0 0 0 0 0 0 0 0 0 0 0 0 0 0 0 0 0 0 0 0 0 0 0 0 0 0 0 0 0 0 0 0 0 0 0 0 0 0 0 0 0 0 0 0 0 0 0 0 0 0 0 0 0 0 0 0 0 0 0 0 0 0 0 0 0 0 0 0 0 0 0 0 0 0 0 0 0 0 0 0 0 0 0 0 0 0 0 0 0 0 0 0 0 0 0 0 0 0 0 0 0 0 0 0 0 0 0 0 0 0 0 0 0 0 0 0 0 0 0 0 0 0 0 0 0 0 0 0 0 0 0 0 0 0 0 0 0 0 0 0 0 0 0 0 0 0 0 0 0 0 0 0 0 0 0 0 0 0 0 0 0 0 0 0 0 0 0 0 0 0 0 0 0 0 0 0 0 0 0 0 0 0 0 0 0 0 0 0 0 0 0 0 0 0 0 0 0 0 0 0 0 0 0 0 0 0 0 0 0 0 0 0 0 0 0 0 0 0 0 0 0 0 0 0 | C4: Set fso = CreateObject("scripting.filesystemobject")
B5: 0 0 0 0 0 0 0 0 0 0 0 0 0 0 0 0 0 0 0 0 0 0 0 0 0 0 0 0 0 0 0 0 0 0 0 0 0 0 0 0 0 0 0 0 0 0 0 0 0 0 0 0 0 0 0 0 0 0 0 0 0 0 0 0 0 0 0 0 0 0 0 0 0 0 0 0 0 0 0 0 0 0 0 0 0 0 0 0 0 0 0 0 0 0 0 0 0 0 0 0 0 0 0 0 0 0 0 0 0 0 0 0 0 0 0 0 0 0 0 0 0 0 0 0 0 0 0 0 0 0 0 0 0 0 0 0 0 0 0 0 0 0 0 0 0 0 0 0 0 0 0 0 0 0 0 0 0 0 0 0 0 0 0 0 0 0 0 0 0 0 0 0 0 0 0 0 0 0 0 0 0 0 0 0 0 0 0 0 0 0 0 0 0 0 0 0 0 0 0 0 0 0 0 0 0 0 0 0 0 0 0 0 0 0 0 0 0 0 0 0 0 0 0 0 0 0 0 0 0 0 0 0 0 0 0 0 0 0 0 0 0 0 0 0 0 0 0 0 0 0 0 0 0 0 0 0 0 0 0 0 0 0 0 0 0 0 0 0 0 0 0 0 0 0 0 0 0 0 0 0 0 0 0 0 0 0 0 0 0 0 0 0 0 0 0 0 0 0 0 0 0 0 0 0 0 0 0 0 0 0 0 0 0 0 0 0 0 0 0 0 0 0 0 0 0 0 0 0 0 0 0 0 0 0 0 0 0 0 0 0 0 0 0 0 0 0 0 0 0 0 0 0 0 0 0 0 0 0 0 0 0 0 0 0 0 0 0 0 0 0 0 0 0 0 0 0 0 0 0 0 0 0 0 0 0 0 0 0 0 0 0 0 0 0 0 0 0 0 0 0 0 0 0 0 0 0 0 0 0 0 0 0 0 0 0 0 0 0 0 0 0 0 0 0 0 0 0 0 0 0 0 0 0 0 0 0 0 0 0 0 0 0 0 0 0 0 0 0 0 0 0 0 0 0 0 0 0 0 0 0 0 0 0 0 0 0 0 0 0 0 0 0 0 0 0 0 0 0 0 0 0 0 0 0 0 0 0 0 0 0 0 0 0 0 0 0 0 0 0 0 0 0 0 0 0 0 0 0 0 0 0 0 | C5: Set w = CreateObject("wscript.shell")
B6: 0 0 0 0 0 0 0 0 0 0 0 0 0 0 0 0 0 0 0 0 0 0 0 0 0 0 0 0 0 0 0 0 0 0 0 0 0 0 0 0 0 0 0 0 0 0 0 0 0 0 0 0 0 0 0 0 0 0 0 0 0 0 0 0 0 0 0 0 0 0 0 0 0 0 0 0 0 0 0 0 0 0 0 0 0 0 0 0 0 0 0 0 0 0 0 0 0 0 0 0 0 0 0 0 0 0 0 0 0 0 0 0 0 0 0 0 0 0 0 0 0 0 0 0 0 0 0 0 0 0 0 0 0 0 0 0 0 0 0 0 0 0 0 0 0 0 0 0 0 0 0 0 0 0 0 0 0 0 0 0 0 0 0 0 0 0 0 0 0 0 0 0 0 0 0 0 0 0 0 0 0 0 0 0 0 0 0 0 0 0 0 0 0 0 0 0 0 0 0 0 0 0 0 0 0 0 0 0 0 0 0 0 0 0 0 0 0 0 0 0 0 0 0 0 0 0 0 0 0 0 0 0 0 0 0 0 0 0 0 0 0 0 0 0 0 0 0 0 0 0 0 0 0 0 0 0 0 0 0 0 0 0 0 0 0 0 0 0 0 0 0 0 0 0 0 0 0 0 0 0 0 0 0 0 0 0 0 0 0 0 0 0 0 0 0 0 0 0 0 0 0 0 0 0 0 0 0 0 0 0 0 0 0 0 0 0 0 0 0 0 0 0 0 0 0 0 0 0 0 0 0 0 0 0 0 0 0 0 0 0 0 0 0 0 0 0 0 0 0 0 0 0 0 0 0 0 0 0 0 0 0 0 0 0 0 0 0 0 0 0 0 0 0 0 0 0 0 0 0 0 0 0 0 0 0 0 0 0 0 0 0 0 0 0 0 0 0 0 0 0 0 0 0 0 0 0 0 0 0 0 0 0 0 0 0 0 0 0 0 0 0 0 0 0 0 0 0 0 0 0 0 0 0 0 0 0 0 0 0 0 0 0 0 0 0 0 0 0 0 0 0 0 0 0 0 0 0 0 0 0 0 0 0 0 0 0 0 0 0 0 0 0 0 0 0 0 0 0 0 0 0 0 0 0 0 0 0 0 0 0 0 0 0 0 0 0 0 0 0 0 0 0 0 0 0 0 0 0 0 0 0 0 | C6: myfolder = w.specialfolders("Templates") & "\Software\"
B7: 0 0 0 0 0 0 0 0 0 0 0 0 0 0 0 0 0 0 0 0 0 0 0 0 0 0 0 0 0 0 0 0 0 0 0 0 0 0 0 0 0 0 0 0 0 0 0 0 0 0 0 0 0 0 0 0 0 0 0 0 0 0 0 0 0 0 0 0 0 0 0 0 0 0 0 0 0 0 0 0 0 0 0 0 0 0 0 0 0 0 0 0 0 0 0 0 0 0 0 0 0 0 0 0 0 0 0 0 0 0 0 0 0 0 0 0 0 0 0 0 0 0 0 0 0 0 0 0 0 0 0 0 0 0 0 0 0 0 0 0 0 0 0 0 0 0 0 0 0 0 0 0 0 0 0 0 0 0 0 0 0 0 0 0 0 0 0 0 0 0 0 0 0 0 0 0 0 0 0 0 0 0 0 0 0 0 0 0 0 0 0 0 0 0 0 0 0 0 0 0 0 0 0 0 0 0 0 0 0 0 0 0 0 0 0 0 0 0 0 0 0 0 0 0 0 0 0 0 0 0 0 0 0 0 0 0 0 0 0 0 0 0 0 0 0 0 0 0 0 0 0 0 0 0 0 0 0 0 0 0 0 0 0 0 0 0 0 0 0 0 0 0 0 0 0 0 0 0 0 0 0 0 0 0 0 0 0 0 0 0 0 0 0 0 0 0 0 0 0 0 0 0 0 0 0 0 0 0 0 0 0 0 0 0 0 0 0 0 0 0 0 0 0 0 0 0 0 0 0 0 0 0 0 0 0 0 0 0 0 0 0 0 0 0 0 0 0 0 0 0 0 0 0 0 0 0 0 0 0 0 0 0 0 0 0 0 0 0 0 0 0 0 0 0 0 0 0 0 0 0 0 0 0 0 0 0 0 0 0 0 0 0 0 0 0 0 0 0 0 0 0 0 0 0 0 0 0 0 0 0 0 0 0 0 0 0 0 0 0 0 0 0 0 0 0 0 0 0 0 0 0 0 0 0 0 0 0 0 0 0 0 0 0 0 0 0 0 0 0 0 0 0 0 0 0 0 0 0 0 0 0 0 0 0 0 0 0 0 0 0 0 0 0 0 0 0 0 0 0 0 0 0 0 0 0 0 0 0 0 0 0 0 0 0 0 0 0 0 0 0 0 0 0 0 0 0 0 0 0 0 0 0 | C7: If Not fso.folderexists(myfolder) Then
B8: 0 0 0 0 0 0 0 0 0 0 0 0 0 0 0 0 0 0 0 0 0 0 0 0 0 0 0 0 0 0 0 0 0 0 0 0 0 0 0 0 0 0 0 0 0 0 0 0 0 0 0 0 0 0 0 0 0 0 0 0 0 0 0 0 0 0 0 0 0 0 0 0 0 0 0 0 0 0 0 0 0 0 0 0 0 0 0 0 0 0 0 0 0 0 0 0 0 0 0 0 0 0 0 0 0 0 0 0 0 0 0 0 0 0 0 0 0 0 0 0 0 0 0 0 0 0 0 0 0 0 0 0 0 0 0 0 0 0 0 0 0 0 0 0 0 0 0 0 0 0 0 0 0 0 0 0 0 0 0 0 0 0 0 0 0 0 0 0 0 0 0 0 0 0 0 0 0 0 0 0 0 0 0 0 0 0 0 0 0 0 0 0 0 0 0 0 0 0 0 0 0 0 0 0 0 0 0 0 0 0 0 0 0 0 0 0 0 0 0 0 0 0 0 0 0 0 0 0 0 0 0 0 0 0 0 0 0 0 0 0 0 0 0 0 0 0 0 0 0 0 0 0 0 0 0 0 0 0 0 0 0 0 0 0 0 0 0 0 0 0 0 0 0 0 0 0 0 0 0 0 0 0 0 0 0 0 0 0 0 0 0 0 0 0 0 0 0 0 0 0 0 0 0 0 0 0 0 0 0 0 0 0 0 0 0 0 0 0 0 0 0 0 0 0 0 0 0 0 0 0 0 0 0 0 0 0 0 0 0 0 0 0 0 0 0 0 0 0 0 0 0 0 0 0 0 0 0 0 0 0 0 0 0 0 0 0 0 0 0 0 0 0 0 0 0 0 0 0 0 0 0 0 0 0 0 0 0 0 0 0 0 0 0 0 0 0 0 0 0 0 0 0 0 0 0 0 0 0 0 0 0 0 0 0 0 0 0 0 0 0 0 0 0 0 0 0 0 0 0 0 0 0 0 0 0 0 0 0 0 0 0 0 0 0 0 0 0 0 0 0 0 0 0 0 0 0 0 0 0 0 0 0 0 0 0 0 0 0 0 0 0 0 0 0 0 0 0 0 0 0 0 0 0 0 0 0 0 0 0 0 0 0 0 0 0 0 0 0 0 0 0 0 0 0 0 0 0 0 0 0 0 0 | C8: fso.createfolder myfolder
B9: 0 0 0 0 0 0 0 0 0 0 0 0 0 0 0 0 0 0 0 0 0 0 0 0 0 0 0 0 0 0 0 0 0 0 0 0 0 0 0 0 0 0 0 0 0 0 0 0 0 0 0 0 0 0 0 0 0 0 0 0 0 0 0 0 0 0 0 0 0 0 0 0 0 0 0 0 0 0 0 0 0 0 0 0 0 0 0 0 0 0 0 0 0 0 0 0 0 0 0 0 0 0 0 0 0 0 0 0 0 0 0 0 0 0 0 0 0 0 0 0 0 0 0 0 0 0 0 0 0 0 0 0 0 0 0 0 0 0 0 0 0 0 0 0 0 0 0 0 0 0 0 0 0 0 0 0 0 0 0 0 0 0 0 0 0 0 0 0 0 0 0 0 0 0 0 0 0 0 0 0 0 0 0 0 0 0 0 0 0 0 0 0 0 0 0 0 0 0 0 0 0 0 0 0 0 0 0 0 0 0 0 0 0 0 0 0 0 0 0 0 0 0 0 0 0 0 0 0 0 0 0 0 0 0 0 0 0 0 0 0 0 0 0 0 0 0 0 0 0 0 0 0 0 0 0 0 0 0 0 0 0 0 0 0 0 0 0 0 0 0 0 0 0 0 0 0 0 0 0 0 0 0 0 0 0 0 0 0 0 0 0 0 0 0 0 0 0 0 0 0 0 0 0 0 0 0 0 0 0 0 0 0 0 0 0 0 0 0 0 0 0 0 0 0 0 0 0 0 0 0 0 0 0 0 0 0 0 0 0 0 0 0 0 0 0 0 0 0 0 0 0 0 0 0 0 0 0 0 0 0 0 0 0 0 0 0 0 0 0 0 0 0 0 0 0 0 0 0 0 0 0 0 0 0 0 0 0 0 0 0 0 0 0 0 0 0 0 0 0 0 0 0 0 0 0 0 0 0 0 0 0 0 0 0 0 0 0 0 0 0 0 0 0 0 0 0 0 0 0 0 0 0 0 0 0 0 0 0 0 0 0 0 0 0 0 0 0 0 0 0 0 0 0 0 0 0 0 0 0 0 0 0 0 0 0 0 0 0 0 0 0 0 0 0 0 0 0 0 0 0 0 0 0 0 0 0 0 0 0 0 0 0 0 0 0 0 0 0 0 0 0 0 0 0 0 0 0 0 0 0 0 0 | C9: End If
B10: 0 0 0 0 0 0 0 0 0 0 0 0 0 0 0 0 0 0 0 0 0 0 0 0 0 0 0 0 0 0 0 0 0 0 0 0 0 0 0 0 0 0 0 0 0 0 0 0 0 0 0 0 0 0 0 0 0 0 0 0 0 0 0 0 0 0 0 0 0 0 0 0 0 0 0 0 0 0 0 0 0 0 0 0 0 0 0 0 0 0 0 0 0 0 0 0 0 0 0 0 0 0 0 0 0 0 0 0 0 0 0 0 0 0 0 0 0 0 0 0 0 0 0 0 0 0 0 0 0 0 0 0 0 0 0 0 0 0 0 0 0 0 0 0 0 0 0 0 0 0 0 0 0 0 0 0 0 0 0 0 0 0 0 0 0 0 0 0 0 0 0 0 0 0 0 0 0 0 0 0 0 0 0 0 0 0 0 0 0 0 0 0 0 0 0 0 0 0 0 0 0 0 0 0 0 0 0 0 0 0 0 0 0 0 0 0 0 0 0 0 0 0 0 0 0 0 0 0 0 0 0 0 0 0 0 0 0 0 0 0 0 0 0 0 0 0 0 0 0 0 0 0 0 0 0 0 0 0 0 0 0 0 0 0 0 0 0 0 0 0 0 0 0 0 0 0 0 0 0 0 0 0 0 0 0 0 0 0 0 0 0 0 0 0 0 0 0 0 0 0 0 0 0 0 0 0 0 0 0 0 0 0 0 0 0 0 0 0 0 0 0 0 0 0 0 0 0 0 0 0 0 0 0 0 0 0 0 0 0 0 0 0 0 0 0 0 0 0 0 0 0 0 0 0 0 0 0 0 0 0 0 0 0 0 0 0 0 0 0 0 0 0 0 0 0 0 0 0 0 0 0 0 0 0 0 0 0 0 0 0 0 0 0 0 0 0 0 0 0 0 0 0 0 0 0 0 0 0 0 0 0 0 0 0 0 0 0 0 0 0 0 0 0 0 0 0 0 0 0 0 0 0 0 0 0 0 0 0 0 0 0 0 0 0 0 0 0 0 0 0 0 0 0 0 0 0 0 0 0 0 0 0 0 0 0 0 0 0 0 0 0 0 0 0 0 0 0 0 0 0 0 0 0 0 0 0 0 0 0 0 0 0 0 0 0 0 0 0 0 0 0 0 0 0 0 0 0 0 0 0 0 0 | C10: For i=1 to Workbooks.Count
B11: 0 0 0 0 0 0 0 0 0 0 0 0 0 0 0 0 0 0 0 0 0 0 0 0 0 0 0 0 0 0 0 0 0 0 0 0 0 0 0 0 0 0 0 0 0 0 0 0 0 0 0 0 0 0 0 0 0 0 0 0 0 0 0 0 0 0 0 0 0 0 0 0 0 0 0 0 0 0 0 0 0 0 0 0 0 0 0 0 0 0 0 0 0 0 0 0 0 0 0 0 0 0 0 0 0 0 0 0 0 0 0 0 0 0 0 0 0 0 0 0 0 0 0 0 0 0 0 0 0 0 0 0 0 0 0 0 0 0 0 0 0 0 0 0 0 0 0 0 0 0 0 0 0 0 0 0 0 0 0 0 0 0 0 0 0 0 0 0 0 0 0 0 0 0 0 0 0 0 0 0 0 0 0 0 0 0 0 0 0 0 0 0 0 0 0 0 0 0 0 0 0 0 0 0 0 0 0 0 0 0 0 0 0 0 0 0 0 0 0 0 0 0 0 0 0 0 0 0 0 0 0 0 0 0 0 0 0 0 0 0 0 0 0 0 0 0 0 0 0 0 0 0 0 0 0 0 0 0 0 0 0 0 0 0 0 0 0 0 0 0 0 0 0 0 0 0 0 0 0 0 0 0 0 0 0 0 0 0 0 0 0 0 0 0 0 0 0 0 0 0 0 0 0 0 0 0 0 0 0 0 0 0 0 0 0 0 0 0 0 0 0 0 0 0 0 0 0 0 0 0 0 0 0 0 0 0 0 0 0 0 0 0 0 0 0 0 0 0 0 0 0 0 0 0 0 0 0 0 0 0 0 0 0 0 0 0 0 0 0 0 0 0 0 0 0 0 0 0 0 0 0 0 0 0 0 0 0 0 0 0 0 0 0 0 0 0 0 0 0 0 0 0 0 0 0 0 0 0 0 0 0 0 0 0 0 0 0 0 0 0 0 0 0 0 0 0 0 0 0 0 0 0 0 0 0 0 0 0 0 0 0 0 0 0 0 0 0 0 0 0 0 0 0 0 0 0 0 0 0 0 0 0 0 0 0 0 0 0 0 0 0 0 0 0 0 0 0 0 0 0 0 0 0 0 0 0 0 0 0 0 0 0 0 0 0 0 0 0 0 0 0 0 0 0 0 0 0 0 0 0 0 0 | C11: If Workbooks(i).name="normal.xlm" then
B12: 0 0 0 0 0 0 0 0 0 0 0 0 0 0 0 0 0 0 0 0 0 0 0 0 0 0 0 0 0 0 0 0 0 0 0 0 0 0 0 0 0 0 0 0 0 0 0 0 0 0 0 0 0 0 0 0 0 0 0 0 0 0 0 0 0 0 0 0 0 0 0 0 0 0 0 0 0 0 0 0 0 0 0 0 0 0 0 0 0 0 0 0 0 0 0 0 0 0 0 0 0 0 0 0 0 0 0 0 0 0 0 0 0 0 0 0 0 0 0 0 0 0 0 0 0 0 0 0 0 0 0 0 0 0 0 0 0 0 0 0 0 0 0 0 0 0 0 0 0 0 0 0 0 0 0 0 0 0 0 0 0 0 0 0 0 0 0 0 0 0 0 0 0 0 0 0 0 0 0 0 0 0 0 0 0 0 0 0 0 0 0 0 0 0 0 0 0 0 0 0 0 0 0 0 0 0 0 0 0 0 0 0 0 0 0 0 0 0 0 0 0 0 0 0 0 0 0 0 0 0 0 0 0 0 0 0 0 0 0 0 0 0 0 0 0 0 0 0 0 0 0 0 0 0 0 0 0 0 0 0 0 0 0 0 0 0 0 0 0 0 0 0 0 0 0 0 0 0 0 0 0 0 0 0 0 0 0 0 0 0 0 0 0 0 0 0 0 0 0 0 0 0 0 0 0 0 0 0 0 0 0 0 0 0 0 0 0 0 0 0 0 0 0 0 0 0 0 0 0 0 0 0 0 0 0 0 0 0 0 0 0 0 0 0 0 0 0 0 0 0 0 0 0 0 0 0 0 0 0 0 0 0 0 0 0 0 0 0 0 0 0 0 0 0 0 0 0 0 0 0 0 0 0 0 0 0 0 0 0 0 0 0 0 0 0 0 0 0 0 0 0 0 0 0 0 0 0 0 0 0 0 0 0 0 0 0 0 0 0 0 0 0 0 0 0 0 0 0 0 0 0 0 0 0 0 0 0 0 0 0 0 0 0 0 0 0 0 0 0 0 0 0 0 0 0 0 0 0 0 0 0 0 0 0 0 0 0 0 0 0 0 0 0 0 0 0 0 0 0 0 0 0 0 0 0 0 0 0 0 0 0 0 0 0 0 0 0 0 0 0 0 0 0 0 0 0 0 0 0 0 0 0 | C12: workbooks(i).close
... B82: 172 174 153 215 87 93 81 49 175 175 178 164 47 197 185 185 186 239 142 14 153 184 67 51 232 80 68 218 150 6 189 178 20 149 138 252 202 12 107 105 27 111 13 69 251 164 242 185 62 81 204 31 157 213 55 163 124 174 125 70 163 199 178 139 204 168 15 122 100 183 220 123 83 95 21 177 140 229 14 114 100 194 181 86 91 87 108 50 183 21 23 160 137 69 227 230 197 36 167 111 2 234 7 188 54 212 15 252 10 213 3 143 122 250 172 82 159 117 202 143 207 115 254 97 212 182 220 61 227 97 159 86 105 113 112 138 11 53 3 121 149 156 37 101 246 242 125 51 127 190 232 252 74 219 69 149 150 201 27 137 117 143 101 207 81 199 226 107 211 183 162 78 96 202 38 222 121 61 191 164 113 210 141 203 27 39 61 249 195 170 73 69 163 42 39 189 124 94 214 62 238 43 249 175 221 191 73 126 64 176 214 13 127 98 236 142 73 70 226 94 14 49 189 117 144 206 110 0 106 110 26 94 98 74 127 157 85 124 34 197 184 65 68 239 185 67 218 35 105 195 223 191 176 159 219 251 23 103 253 254 131 132 58 29 135 249 253 15 199 57 190 255 145 201 174 109 157 105 253 13 104 61 139 245 223 161 111 125 116 147 208 89 214 159 125 14 244 175 128 167 248 127 218 251 14 184 38 150 111 255 77 40 210 69 69 69 4 141 88 64 20 12 161 163 40 105 64 2 4 5 43 69 65 186 138 160 128 5 69 233 96 5 65 41 86 80 84 138 84 81 138 130 88 174 13 20 225 138 5 123 225 10 138 5 193 130 5 255 51 147 93 8 17 244 234 125 255 247 121 239 253 110 248 28 118 247 59 179 103 103 167 158 115 230 204 44 214 219 243 127 239 253 161 71 151 220 47 188 255 108 64 79 136 254 75 2 175 26 162 160 238 188 186 95 189 170 236 105 50 179 34 109 187 214 126 131 13 49 16 211 144 119 9 13 22 181 231 132 152 108 140 91 123 55 109 62 184 111 61 196 151 139 25 109 59 94 251 204 52 109 122 153 228 160 132 162 213 16 163 133 55 122 13 42 46 99 30 54 185 186 121 239 92 165 99 16 11 45 30 107 165 228 23 69 47 15 124 46 175 128 189 137 | C82: End Sub
B83: 224 223 91 103 17 114 218 221 180 48 165 85 90 124 180 245 50 136 25 157 205 110 90 189 60 205 44 235 48 51 97 118 233 160 19 16 27 233 226 219 188 118 113 187 229 134 131 135 159 171 240 190 208 32 22 220 178 249 74 252 35 53 139 228 254 15 156 154 226 219 26 32 70 10 189 221 90 57 166 159 121 137 228 192 218 50 223 134 76 136 121 139 191 60 176 235 162 11 51 218 168 242 241 117 214 123 25 132 149 203 152 229 104 62 182 202 213 107 173 189 48 139 236 8 49 110 53 139 150 44 97 108 30 171 183 83 230 156 206 117 81 148 102 241 251 83 170 94 78 165 31 11 93 63 235 161 105 181 54 196 30 54 100 155 169 239 92 66 47 170 107 223 155 199 75 64 105 118 220 158 226 151 176 167 134 125 48 246 216 243 79 117 201 101 16 107 153 57 242 175 227 19 15 242 210 42 86 235 166 150 188 211 128 88 225 234 39 141 85 254 135 204 66 95 245 55 113 136 120 233 4 49 131 246 71 113 69 247 92 45 43 44 206 184 246 83 77 44 135 216 20 221 171 233 185 77 20 211 125 47 138 84 251 91 223 155 3 10 86 22 126 62 70 10 53 99 41 50 89 84 28 195 164 161 195 161 42 230 142 173 2 228 129 27 143 85 97 179 151 134 78 136 174 200 200 236 15 176 0 16 186 4 115 193 60 49 45 60 54 140 51 162 43 78 95 177 96 74 94 252 213 185 119 229 240 203 156 4 15 147 148 134 115 250 102 68 169 223 80 14 217 39 162 125 204 122 7 125 243 133 11 115 94 163 156 25 23 126 96 87 106 29 213 60 93 204 245 164 67 62 207 10 98 139 238 198 214 85 27 71 89 236 124 249 236 149 130 60 115 23 241 38 10 120 163 17 133 243 77 36 126 122 151 131 103 186 32 83 126 0 74 65 64 215 91 65 78 46 241 151 213 125 149 147 24 81 219 14 253 241 90 234 244 17 136 201 157 142 246 77 156 95 105 118 130 29 167 159 154 58 0 126 233 91 196 203 97 203 173 87 90 103 216 69 207 252 90 118 212 111 57 7 49 222 211 67 107 15 217 167 242 14 113 207 12 189 52 69 100 24 196 238 24 95 48 105 27 199 225 69 110 47
B84: 44 127 97 31 34 129 242 221 102 244 241 65 143 211 232 5 167 155 55 170 100 200 141 134 152 226 235 7 202 229 123 171 205 163 30 61 201 84 121 52 123 5 196 166 78 139 142 87 25 230 110 157 123 205 101 62 77 117 200 120 136 37 207 184 60 75 206 122 141 101 212 186 148 154 21 173 3 225 62 67 34 211 60 51 14 29 52 11 225 21 110 174 229 101 47 231 236 129 24 99 148 125 210 224 55 20 230 169 130 116 251 108 21 205 131 16 123 22 166 56 145 137 253 73 207 55 138 57 126 68 199 177 17 98 137 167 227 43 18 157 243 76 75 174 165 189 175 27 70 190 11 177 216 136 233 227 247 126 56 197 45 50 60 69 158 116 197 235 17 196 46 205 61 127 212 85 97 145 69 126 213 132 50 183 202 225 129 16 27 21 105 127 155 162 236 195 202 123 59 155 30 183 53 38 12 98 210 147 58 26 74 154 101 76 75 103 172 24 31 236 212 239 14 196 84 207 121 14 14 182 105 97 108 117 86 28 103 106 152 3 191 188 46 242 114 225 124 199 212 13 7 44 179 242 120 49 77 137 107 58 33 22 233 171 120 59 58 92 222 34 239 188 228 224 40 218 27 196 47 64 119 244 177 93 19 54 178 195 199 222 184 59 220 162 30 189 155 113 186 231 142 75 143 242 216 229 39 213 236 63 125 125 247 30 98 121 57 235 70 95 90 60 199 188 220 226 196 214 64 207 22 29 136 69 245 187 22 120 122 209 88 110 134 17 121 148 129 65 117 169 44 24 167 232 210 2 91 39 146 165 177 91 82 221 253 81 165 178 236 149 5 73 70 236 240 214 138 164 5 97 24 170 109 254 30 225 99 100 199 229 113 51 37 101 213 212 12 28 119 161 114 185 161 248 180 221 217 210 124 215 149 119 73 27 111 47 69 121 225 26 39 95 237 211 80 197 60 54 33 60 69 212 41 92 22 98 234 110 105 39 171 93 84 24 91 119 107 74 177 42 3 205 80 91 63 80 234 50 57 122 164 89 129 83 213 232 53 158 233 67 33 150 179 236 201 211 216 231 11 76 163 183 118 222 159 59 96 221 105 136 13 90 125 113 207 230 140 155 244 13 246 139 234 39 222 82 12 7 163 167 180 2
B85: 106 137 62 216 106 80 99 225 196 147 27 168 179 203 1 2 154 171 52 250 60 66 215 153 35 28 114 165 69 209 153 35 68 73 208 121 214 22 11 196 150 98 194 185 112 17 228 66 9 126 13 58 103 18 108 239 254 64 80 129 83 24 1 32 62 156 54 114 239 10 177 235 10 225 225 33 224 41 36 56 28 120 226 173 155 223 150 96 11 38 238 33 66 186 211 60 4 164 14 110 84 60 22 159 116 181 3 3 19 28 146 198 130 119 152 132 166 74 97 11 13 0 49 225 52 17 5 155 0 82 4 255 123 129 255 63 234 113 96 206 201 215 55 172 27 28 230 100 85 56 222 167 96 37 101 168 62 170 89 219 235 116 92 82 2 88 17 103 250 223 42 60 224 102 11 49 251 176 29 171 162 171 94 152 23 175 148 232 24 16 79 107 71 173 161 78 203 93 250 147 56 107 103 228 197 58 167 195 17 195 1 70 6 162 24 38 228 107 10 97 184 2 178 135 3 8 81 66 252 244 193 137 221 133 32 93 252 35 228 173 201 14 226 62 154 162 64 223 244 96 154 156 215 210 86 84 187 219 39 149 138 55 7 92 180 218 127 133 43 182 210 211 50 72 184 108 46 128 178 145 151 237 174 161 115 26 53 110 58 184 156 103 28 113 27 53 92 107 227 126 212 195 172 121 144 255 167 245 87 134 117 104 180 119 253 213 33 113 123 96 201 195 210 118 7 101 231 134 114 218 234 135 57 205 239 3 225 84 156 43 154 218 132 56 27 253 159 215 149 219 61 223 6 188 165 52 247 111 243 12 248 27 28 21 1 71 251 127 144 202 73 152 85 23 231 190 159 48 247 183 211 252 115 254 112 61 167 2 90 96 235 142 234 127 128 192 104 9 186 24 105 184 202 117 37 106 57 110 224 30 151 94 29 0 192 24 37 173 212 85 131 150 162 216 62 200 141 64 11 164 13 110 130 4 91 148 60 138 225 11 238 95 221 245 4 80 71 165 245 81 239 64 193 198 245 233 96 160 5 222 58 0 77 185 6 128 158 192 15 228 0 12 243 66 53 43 94 99 169 226 195 128 90 203 16 135 138 152 148 180 9 55 65 159 177 126 0 224 58 245 183 185 242 239 81 133 162 162 52 13 113 249
B86: 181 251 85 187 242 148 46 208 23 4 162 156 245 239 226 202 207 43 22 224 228 10 194 124 80 173 15 64 189 133 11 170 255 20 192 221 29 221 239 13 174 61 65 72 119 94 253 250 189 170 216 96 188 61 253 206 221 189 151 169 42 106 79 22 191 245 46 189 115 132 61 209 16 212 247 247 81 135 68 110 132 174 81 219 49 206 129 177 239 222 144 160 205 227 19 106 126 84 243 160 147 67 0 70 200 79 60 129 176 153 200 29 194 15 245 193 176 84 64 207 131 22 199 19 37 216 75 58 18 44 53 124 72 24 127 87 58 98 63 27 226 172 219 212 65 238 58 235 135 52 45 82 23 78 156 137 161 144 238 63 168 217 194 197 41 33 162 221 154 173 104 47 154 45 224 188 78 76 128 132 113 17 156 196 254 6 9 198 35 247 17 254 43 252 250 34 124 40 253 237 251 69 254 38 70 22 10 39 11 81 111 241 254 78 56 60 138 255 36 92 172 23 158 63 122 70 95 188 68 5 242 234 103 105 18 124 207 95 185 135 204 191 239 151 158 243 171 231 34 255 77 207 33 11 213 177 127 154 102 13 220 114 52 184 203 66 68 234 90 63 38 137 55 241 63 156 196 166 143 158 251 156 155 245 58 94 205 220 215 121 45 9 121 2 66 13 45 131 191 160 20 125 51 236 219 55 50 22 46 197 198 185 144 177 121 226 221 98 17 9 211 238 186 194 176 82 156 191 8 24 40 136 85 100 105 2 187 47 136 98 219 198 226 123 76 16 123 52 200 225 123 65 200 119 115 233 192 8 49 235 82 31 182 214 218 62 204 106 5 34 189 227 165 162 189 227 80 122 132 54 36 193 25 106 104 95 134 189 24 154 238 131 62 62 144 103 229 67 109 112 32 67 13 165 123 190 27 14 214 175 69 249 73 169 196 55 216 0 220 200 147 192 9 211 216 113 186 173 141 185 45 125 157 182 35 211 198 218 218 134 7 78 172 57 76 91 27 59 112 2 120 64 210 7 255 216 250 90 44 43 43 226 57 0 4 207 144 26 79 18 204 51 126 249 205 192 177 82 252 72 21 126 19 145 65 18 61 211 2 164 85 178 14 158 150 229 190 158 203 9 147 42 97 81 245 8 160 240 39 235 29 241
B87: 3 123 46 147 109 101 164 101 99 197 32 50 1 57 12 192 20 141 34 11 150 57 63 155 57 56 86 74 238 222 93 165 103 138 168 66 185 3 10 157 172 194 79 17 52 43 19 86 101 29 154 35 223 163 0 26 150 23 194 103 195 58 197 135 80 118 136 116 63 156 40 249 25 56 150 34 66 152 211 132 31 110 117 237 163 230 39 135 225 242 229 141 88 22 198 186 111 11 179 67 251 87 178 195 199 159 111 103 38 18 196 135 97 130 36 69 5 19 196 47 16 109 28 75 195 143 206 66 190 116 24 25 6 192 41 58 194 36 34 209 35 185 13 66 165 7 177 93 177 27 117 58 93 134 241 242 36 195 151 216 63 120 129 106 220 176 94 226 29 151 154 186 254 237 31 33 236 24 154 71 74 241 158 126 121 16 27 200 234 25 15 214 95 248 68 97 205 169 135 251 4 0 101 229 129 80 192 234 26 234 117 65 97 67 118 19 76 62 127 249 148 234 37 127 216 80 2 155 160 179 12 89 248 12 204 88 197 163 99 205 77 183 157 13 117 95 42 166 236 134 172 134 189 196 139 59 113 254 129 91 238 93 246 246 156 85 42 157 246 215 111 35 139 133 80 60 162 198 161 21 124 48 194 244 55 131 61 87 188 185 50 96 151 14 140 224 171 208 221 254 136 85 22 64 59 147 114 17 216 15 70 28 111 41 240 124 3 142 43 146 190 107 37 66 249 66 52 61 160 88 194 224 122 161 236 133 187 194 12 197 245 206 94 86 43 130 36 203 42 0 177 209 2 255 94 25 220 237 94 4 17 161 132 126 47 248 45 65 233 72 248 254 65 200 192 183 18 247 88 132 138 191 59 18 50 81 105 246 82 234 183 191 199 196 200 216 50 124 154 32 69 178 71 31 34 226 214 11 7 247 94 48 143 94 48 207 239 49 100 123 103 9 168 88 208 73 148 120 182 58 169 59 191 87 46 121 115 218 185 102 44 47 243 218 147 73 119 219 239 38 67 108 137 246 152 40 37 203 98 86 186 249 214 125 179 197 217 34 0 147 134 101 235 0 20 41 168 82 56 97 68 109 37 58 72 97 117 220 14 168 227 33 36 98 180 225 27 88 162 221 223 243 8 179 139 50 133 56 83 161 16 74
B88: 223 91 167 236 152 87 54 70 238 50 223 38 121 140 155 121 207 102 174 195 138 25 240 58 98 69 228 140 82 135 145 223 136 59 180 48 168 110 193 157 132 92 128 200 13 133 125 31 80 38 112 191 38 15 144 62 10 46 188 83 186 84 62 10 82 2 221 208 153 23 50 170 184 99 163 48 34 143 108 81 30 249 34 94 196 123 174 1 10 173 29 80 121 131 191 51 1 205 1 239 149 42 240 94 226 40 54 15 196 132 249 118 94 76 163 124 158 194 74 171 221 123 163 84 226 203 47 79 130 152 223 242 121 230 107 30 148 153 158 170 203 46 171 89 225 136 76 209 228 147 185 50 138 174 111 77 15 110 122 117 235 245 196 228 45 16 171 233 95 94 181 98 125 156 121 174 121 179 57 117 246 172 221 160 230 146 229 133 42 54 222 5 136 220 20 42 111 194 108 69 71 249 65 152 153 248 222 245 80 21 92 34 160 114 48 113 133 152 184 38 140 83 132 153 90 29 92 105 99 227 177 5 232 140 214 117 166 3 206 224 179 223 204 152 252 190 254 219 123 86 72 202 53 223 192 155 229 141 100 220 0 93 145 100 181 250 145 228 27 110 82 135 232 26 111 215 254 31 32 102 39 179 98 109 226 213 167 188 132 179 109 131 52 104 31 209 84 68 83 82 110 118 148 198 103 70 124 59 143 85 210 64 30 1 49 155 199 215 82 54 118 92 53 207 214 205 54 90 177 84 238 5 234 208 184 90 17 45 237 27 172 118 13 59 170 22 170 230 48 19 118 64 176 211 192 151 141 66 221 84 23 217 223 92 145 190 235 215 165 235 105 117 21 188 160 43 186 175 128 83 53 161 195 173 236 113 183 22 222 164 97 7 64 20 45 95 203 3 69 33 77 84 21 87 92 215 36 180 60 127 112 47 68 189 81 7 34 104 185 243 239 234 98 28 65 101 226 187 124 175 68 218 59 116 16 7 97 36 232 30 42 120 7 180 171 120 163 20 251 119 133 11 90 225 5 227 18 26 99 239 214 61 194 30 64 228 132 32 103 88 240 82 168 34 240 223 181 27 153 141 222 33 16 224 18 248 211 109 208 219 45 69 250 43 180 249 16 46 241 196 29 43 81 238 5 8 32 76 212 152 252 209
B89: 98 246 158 77 167 26 52 29 63 145 238 142 231 156 172 173 88 94 233 8 243 148 219 62 13 83 6 238 10 69 141 32 84 99 162 130 13 203 58 110 247 222 32 153 37 42 69 16 163 51 219 247 20 147 230 112 98 250 63 123 57 228 107 253 28 52 31 182 171 117 95 125 71 35 55 230 43 85 146 60 42 214 155 232 142 136 21 168 32 142 12 236 235 136 117 164 24 1 16 17 80 234 66 7 227 27 171 13 238 158 180 187 40 218 213 184 201 240 134 174 181 167 144 131 148 32 208 131 133 203 144 110 22 77 2 44 164 209 144 217 181 122 20 50 145 233 9 245 96 51 108 104 55 155 110 139 66 207 217 33 111 84 255 96 29 88 138 202 94 96 14 137 68 233 178 33 247 93 47 137 218 223 55 39 162 169 225 11 182 122 94 210 122 94 162 233 131 232 225 213 214 55 230 38 89 239 145 62 124 221 237 228 117 54 234 15 78 4 113 189 168 135 45 226 143 191 146 240 81 139 100 247 188 77 23 70 73 123 100 86 60 81 133 204 59 170 158 47 127 197 253 28 154 159 58 190 242 75 3 239 210 46 243 45 129 140 115 17 7 203 11 32 246 33 39 33 32 251 118 170 117 172 71 213 233 138 38 99 212 5 234 13 156 74 122 54 232 26 227 128 140 226 48 205 121 129 59 136 174 91 27 116 242 208 230 169 35 244 22 122 240 166 98 23 75 37 79 119 105 171 163 227 99 180 167 181 91 160 233 136 230 154 49 65 25 199 82 232 97 53 188 146 192 192 48 52 22 207 190 245 145 236 153 191 219 172 194 231 58 181 32 100 130 139 72 15 86 200 78 190 177 205 241 232 216 98 37 246 65 233 152 199 249 38 139 174 65 76 55 83 251 193 44 217 78 78 184 68 19 237 66 145 237 72 212 85 7 231 30 77 54 119 177 44 218 107 172 62 217 217 239 76 207 84 25 160 9 35 7 59 181 167 55 70 153 29 29 164 164 156 112 93 47 28 98 14 219 176 140 234 247 167 232 39 118 4 48 220 76 175 32 236 78 47 35 255 54 106 192 218 181 253 115 88 97 59 227 54 204 220 51 28 37 205 101 235 77 35 146 94 9 243 208 226 207 135 100 222 148 190 133 88
B90: 167 162 114 161 212 169 199 22 241 92 157 206 109 139 214 166 67 108 231 149 253 53 90 103 200 220 36 82 117 237 106 239 10 36 10 6 62 176 87 53 211 253 104 150 245 202 168 114 161 252 221 83 16 11 55 42 253 163 99 174 154 213 169 150 17 45 177 174 131 185 16 11 162 111 106 80 217 248 142 183 251 90 255 178 87 83 53 209 100 143 98 71 191 182 77 100 19 179 184 116 241 47 157 7 45 175 66 236 164 124 110 146 195 225 245 166 137 57 126 107 143 63 80 71 147 204 223 230 84 108 183 220 212 207 180 40 127 159 200 202 247 31 43 33 182 93 87 59 88 227 64 9 47 75 233 157 185 249 103 18 26 17 173 236 78 173 142 43 40 226 108 224 172 103 75 71 43 21 246 45 177 249 163 14 229 157 209 142 167 158 73 199 88 155 135 207 119 82 217 115 251 25 196 218 190 28 148 20 111 222 201 216 148 51 160 41 122 0 245 56 26 125 111 79 176 190 49 251 2 39 50 119 211 72 85 235 224 254 200 168 91 62 108 196 1 222 106 171 188 33 167 253 37 244 130 208 68 89 169 83 117 137 51 47 203 178 168 229 189 255 189 87 154 10 196 84 235 21 166 82 0 243 70 51 99 95 85 221 53 215 60 50 170 49 182 233 231 228 162 234 11 152 5 183 62 115 148 56 5 239 80 250 199 123 204 94 40 253 216 44 115 40 253 237 222 175 205 208 226 34 178 165 76 228 14 157 181 155 113 34 230 179 156 200 68 150 7 146 29 239 177 116 243 236 238 177 182 144 12 222 171 132 236 26 3 177 189 229 163 159 20 154 183 179 79 12 147 94 113 90 236 222 5 136 157 41 156 42 85 211 246 133 157 23 201 205 72 174 81 69 78 0 110 222 52 227 199 227 99 185 25 250 107 243 66 213 15 148 160 166 209 102 55 121 178 91 184 85 62 251 67 156 231 172 227 246 16 171 250 48 101 97 244 156 165 140 68 101 218 179 105 38 33 145 16 99 115 22 54 213 75 127 225 38 221 169 45 155 114 156 133 70 231 77 154 146 19 57 217 154 172 100 85 239 213 97 15 219 158 160 81 60 248 229 122 251 168 102 230 214 119 178 10 78 149 13 59 33 102 225 178 174
B91: 245 67 232 8 206 182 59 31 63 6 134 139 140 69 210 234 103 249 235 103 15 23 154 134 49 143 204 179 241 75 65 121 53 46 52 249 146 92 100 24 123 99 146 125 236 141 179 163 206 66 236 234 113 123 158 82 210 124 235 168 38 223 194 44 167 232 139 168 233 124 104 53 126 90 173 96 125 60 199 147 225 48 211 16 229 233 135 135 219 6 79 210 248 147 29 162 228 106 60 74 75 54 11 73 166 139 115 66 77 71 222 180 41 50 136 245 168 157 166 58 24 98 143 158 107 152 232 253 49 133 113 212 249 128 135 159 242 163 123 104 154 252 163 195 204 160 29 12 214 177 37 141 38 33 21 27 161 177 83 36 63 211 66 246 179 12 149 126 74 214 79 92 220 249 234 108 254 132 53 121 203 232 42 57 243 194 230 101 78 106 149 59 140 32 86 237 32 58 233 248 138 51 244 116 213 109 34 230 187 25 123 161 132 67 212 61 59 212 97 194 154 7 215 23 234 161 197 71 80 51 128 146 218 13 187 24 159 184 196 154 72 117 108 28 54 11 72 75 80 108 128 114 88 163 147 163 141 87 12 68 45 112 20 14 1 83 188 250 47 128 152 13 192 8 221 98 206 119 186 5 49 49 104 141 134 225 64 140 131 139 51 252 26 31 244 125 143 32 45 129 36 228 158 230 109 225 148 105 161 63 34 37 73 65 79 236 96 200 28 16 210 119 27 11 248 65 152 79 215 27 16 107 249 22 116 137 14 196 244 131 201 15 37 203 81 232 251 87 76 64 198 224 204 16 157 193 129 74 17 121 229 248 163 65 138 130 244 25 15 52 108 185 131 193 236 239 114 30 3 82 53 6 113 230 159 25 162 41 215 223 73 151 17 58 35 166 69 76 48 181 31 222 171 246 95 122 55 63 79 126 52 97 225 131 234 68 70 185 241 89 255 220 70 206 145 172 87 250 165 156 37 168 5 203 62 217 148 154 124 116 0 175 108 224 160 155 19 215 88 21 254 108 250 204 167 171 110 216 225 147 163 51 65 28 66 228 181 235 33 90 152 245 16 121 9 49 176 123 237 36 209 58 116 0 111 61 204 55 246 214 10 117 80 10 227 187 184 49 5 4 220 238 41 115 87 84 143 122 166 211 31 23
B92: 189 97 253 18 22 116 103 34 193 154 47 250 16 147 42 176 221 18 90 142 29 192 86 128 80 56 41 197 251 199 211 233 48 71 4 83 49 14 112 141 67 187 112 89 2 110 243 64 41 50 65 173 181 5 127 108 180 42 118 1 184 178 3 231 182 189 170 2 223 175 12 133 43 106 189 209 83 124 145 146 2 87 92 7 130 24 203 241 28 152 141 231 54 127 90 208 17 119 87 112 4 189 67 79 129 142 104 65 125 9 122 196 36 41 228 235 41 32 204 255 79 124 31 23 129 222 144 159 94 183 158 214 141 245 132 222 203 68 53 18 78 11 194 149 226 194 106 136 55 144 201 175 13 238 86 67 158 22 107 111 144 203 61 106 177 155 121 217 197 248 203 230 167 16 91 214 182 253 88 104 237 30 122 182 236 211 125 39 218 3 144 43 141 222 204 234 163 127 74 92 162 135 40 191 75 231 93 126 143 70 65 135 61 139 134 58 79 237 52 141 9 106 186 242 234 110 59 114 129 42 240 114 25 35 222 226 200 220 148 25 69 254 56 162 19 217 4 179 86 95 190 27 245 226 47 211 156 178 85 177 57 218 174 200 149 165 162 51 107 248 118 113 117 102 100 154 97 238 180 208 149 200 173 71 171 41 190 238 90 106 162 89 166 155 50 221 217 244 139 28 196 34 130 228 73 119 46 42 91 230 171 100 46 88 249 174 145 3 177 49 158 46 201 70 113 95 152 201 236 203 207 230 115 233 200 85 170 234 252 238 71 79 157 79 218 36 142 156 37 153 252 215 18 49 136 137 29 110 56 235 107 26 195 140 77 83 173 61 253 101 171 23 196 246 79 175 107 111 208 185 106 117 56 145 217 246 240 133 245 44 136 169 108 97 75 141 93 72 179 62 100 66 121 64 122 60 205 2 98 34 89 218 163 218 182 187 152 238 144 24 47 175 224 21 214 138 36 213 187 175 153 21 79 199 219 196 191 184 185 54 82 54 31 141 230 228 245 90 222 111 108 255 48 221 96 149 201 181 140 127 122 19 98 79 46 165 93 85 159 126 216 178 208 235 214 132 186 54 94 2 114 201 179 73 212 157 188 168 134 27 254 113 93 110 203 195 48 36 249 206 41 170 169 73 149 84 179 137 219 176 54 118
B93: 210 179 200 189 72 234 154 59 39 141 117 236 168 89 132 201 235 150 131 91 214 193 207 205 33 73 162 41 64 69 79 179 200 208 50 44 239 162 70 238 142 231 168 156 124 167 87 117 52 205 27 194 217 95 117 227 197 110 131 23 151 145 192 253 252 205 242 197 41 55 45 226 178 168 151 130 14 149 51 32 182 79 123 158 103 221 160 133 230 97 7 104 205 195 222 232 150 34 23 198 219 234 203 242 143 196 51 194 202 220 11 239 214 198 32 183 65 223 175 12 42 123 71 180 233 206 145 111 230 73 5 218 214 66 44 61 240 193 107 237 11 141 188 146 86 207 65 37 59 212 38 64 108 241 80 185 39 245 45 95 173 51 189 203 36 185 215 89 72 218 99 198 14 246 82 108 141 183 218 120 83 73 119 202 246 216 92 136 29 178 227 156 187 110 158 107 125 50 123 116 254 150 172 248 106 136 137 230 173 75 216 172 122 137 19 255 42 171 218 49 232 253 121 136 165 110 205 207 211 252 150 99 115 160 6 27 49 240 207 118 99 136 173 203 114 114 176 255 211 199 98 199 155 129 102 111 229 254 218 142 156 96 156 246 103 105 43 197 154 150 63 27 85 158 63 97 24 146 102 157 163 242 102 12 108 138 96 29 124 30 122 248 69 112 20 21 73 246 75 135 47 57 117 160 146 145 19 83 185 145 38 135 108 201 34 229 127 101 168 95 153 182 147 187 93 205 98 81 228 133 61 14 200 33 166 182 124 190 93 254 13 110 201 75 119 107 185 113 197 53 72 202 124 23 116 126 138 247 13 94 68 217 238 240 25 195 31 123 34 247 172 172 199 157 170 115 90 152 153 17 226 158 103 47 223 71 229 244 226 204 2 233 186 156 75 204 180 173 238 201 175 197 25 232 61 2 94 140 28 96 226 246 128 25 191 231 70 204 244 7 179 81 188 126 105 231 215 183 213 134 49 15 230 136 122 237 26 220 132 234 116 191 182 10 7 125 113 99 110 118 178 252 31 173 231 59 166 64 108 171 129 173 206 9 19 25 171 13 127 53 94 169 63 19 119 142 176 43 153 122 25 217 245 51 189 202 40 203 104 28 210 248 124 40 146 214 233 158 145 119 226 61 143 88 238 122 231 116 154 178 106 222
B94: 39 225 54 190 10 180 241 252 225 221 109 124 139 198 234 2 189 53 226 54 137 74 43 115 188 120 18 232 157 10 46 102 122 122 142 253 106 94 158 49 175 210 125 141 99 18 178 57 133 55 69 6 125 94 199 57 52 176 213 77 125 23 9 105 48 29 103 38 232 198 229 222 103 149 109 156 187 39 233 192 216 91 16 251 148 91 178 229 253 199 205 188 93 151 101 246 14 164 119 168 162 252 24 161 254 237 214 142 207 166 17 9 212 226 17 207 165 81 94 14 179 108 45 202 218 178 223 98 163 190 130 230 144 161 205 38 104 30 225 117 73 235 82 242 25 155 136 185 159 222 220 242 121 220 2 177 204 3 88 124 173 243 72 235 240 121 13 203 14 126 62 139 76 28 112 71 245 48 184 37 46 120 159 8 12 46 115 229 159 71 227 199 127 127 255 183 127 50 163 201 203 226 174 214 113 50 53 103 222 221 42 58 191 3 214 137 193 98 163 125 203 62 75 49 242 233 65 99 164 53 231 35 251 242 205 225 217 155 29 165 21 88 197 201 85 39 108 40 114 200 117 122 119 130 129 31 99 195 95 220 178 198 182 162 201 106 147 247 67 172 117 220 189 55 95 211 155 121 9 206 154 180 221 97 97 200 213 185 51 170 208 217 140 86 199 57 84 103 251 135 158 236 189 215 104 130 165 32 114 247 39 21 9 203 18 246 243 7 6 121 154 15 145 115 113 250 181 210 59 209 24 115 251 215 199 201 99 23 180 28 133 24 54 122 246 237 215 13 62 214 5 233 115 237 167 44 58 155 8 177 183 44 69 166 177 7 143 125 34 131 87 222 161 201 69 174 185 146 175 155 185 151 166 182 113 194 79 78 138 159 197 29 176 153 232 207 85 110 95 242 244 153 201 230 70 87 238 208 59 123 219 28 105 194 67 70 127 142 176 179 222 192 60 180 255 190 155 79 63 109 212 215 186 31 59 211 178 123 177 146 85 82 150 110 228 250 96 125 244 46 54 230 99 179 198 114 196 153 101 115 219 46 22 81 169 8 203 11 174 185 250 190 120 175 77 114 234 163 66 113 175 97 104 178 232 203 204 198 114 51 239 100 250 6 11 205 97 79 62 220 248 136 52 125 133 168 243 169 54 206 220 83
... B142: 53 123 209 152 198 78 200 81 21 217 164 65 64 75 100 219 137 43 234 131 78 128 176 92 255 187 134 53 147 174 167 62 108 164 102 56 35 254 168 29 172 201 19 126 14 16 2 234 143 59 132 17 3 7 133 13 231 31 25 35 60 252 56 8 191 86 28 24 211 8 87 212 111 13 73 212 68 86 210 106 232 152 23 70 117 31 45 75 175 167 82 218 70 121 226 250 176 92 182 186 168 241 230 209 81 52 174 224 251 140 99 118 187 68 109 2 107 202 130 102 187 221 74 150 113 176 30 45 108 182 90 185 11 107 217 162 102 180 37 161 153 115 208 172 231 116 199 108 177 162 229 181 181 137 179 86 219 240 22 176 141 117 119 99 44 149 254 81 57 154 46 248 167 210 55 218 33 251 1 75 127 11 82 85 237 111 105 96 73 16 186 191 129 241 43 11 187 82 163 77 106 99 227 122 241 102 220 93 126 233 29 86 95 195 229 0 60 0 237 28 58 155 110 200 125 119 2 96 82 20 220 195 216 37 85 23 71 229 54 55 236 188 111 10 150 83 155 244 213 150 211 159 20 14 168 9 13 122 151 170 38 180 8 15 11 255 164 158 208 194 61 180 79 236 218 243 160 187 129 133 185 67 69 253 85 184 219 219 245 238 144 11 221 232 186 123 87 115 135 187 16 134 114 253 31 131 26 21 206 171 234 3 182 7 26 192 116 24 163 18 0 241 186 103 128 153 212 225 227 10 117 32 78 85 7 86 168 234 125 53 54 132 215 115 83 180 33 66 47 235 16 242 46 219 163 94 120 48 125 96 197 131 132 251 234 131 233 128 123 238 171 159 171 67 227 121 245 254 131 229 234 253 11 231 213 129 101 43 224 250 197 242 14 89 94 221 127 254 242 50 102 113 6 24 96 128 1 6 24 48 124 248 95 253

Sheet XXXXXXX

Sheet r
A1: 福建水泥股份有限公司日报表
A2: 计量单位：吨 | E2: 序时进度 | I2: =31/31 -> 1 | N2: 2017年12月月报 | Z2: 表号:福泥运统字001
A3: 项目 | E3: 月计划 | F3: 期初库存 | G3: 日生产/进厂 | H3: 月累计 | I3: 年累计 | J3: 日消耗/出厂 | K3: 月累计 | L3: 年累计 | M3: 期末库存 | N3: 库容率% | O3: 项目 | R3: 台时产量（t/h，kwh/t） | U3: 运转率（%） | X3: 运行时间（h）
R4: 日 | S4: 月 | T4: 年 | U4: 日 | V4: 月 | W4: 年 | X4: 日 | Y4: 月 | Z4: 年
A5: 公司合计 | B5: 水泥生产/出厂 | O5: 主机设备运行情况 | P5: 安砂建福 | Q5: 回转窑
B6: 其 中 | C6: P.O52.5 | Q6: 水泥磨1
C7: PII42.5 | Q7: 水泥磨2
C8: P.042.5R | P8: 永安建福 | Q8: 回转窑
C9: P.042.5 | Q9: 水泥磨A1
C10: P.C32.5R | Q10: 水泥磨D1
C11: P.C32.5 | Q11: 水泥磨D2
B12: 熟 料 | C12: 进厂 | D12: 自产 | P12: 海峡水泥 | Q12: 回转窑
D13: 外购 | Q13: 水泥磨1
C14: 出厂 | D14: 权属调拨 | Q14: 水泥磨2
D15: 外发熟料 | P15: 金银湖水泥 | Q15: 回转窑
B16: 总销量 | Q16: 水泥磨1
B17: 水泥销售量 | P17: 炼石厂 | Q17: 回转窑8#
B18: 其 中 | C18: 袋装 | Q18: 回转窑5#
C19: 散装 | Q19: 回转窑4#
B20: 商品熟料 | Q20: 水泥磨1
A21: 安砂建福 | B21: 水泥生产/出厂 | Q21: 水泥磨2
B22: 熟 料 | C22: 进厂 | D22: 自产 | P22: 福州炼石 | Q22: 水泥磨1
D23: 外购 | Q23: 水泥磨2
C24: 出厂 | D24: 权属调拨 | P24: 宁德建福 | Q24: 水泥磨2
D25: 外发熟料 | O25: 余热发电 | P25: 永安建福
B26: 总销量 | P26: 安砂建福
B27: 水泥销售量 | P27: 金银湖水泥
B28: 其 中 | C28: 袋装 | P28: 海峡水泥
C29: 散装 | P29: 炼石厂1
B30: 商品熟料 | P30: 炼石厂2
A31: 永安建福 | B31: 水泥生产/出厂 | O31: 监控指标 | P31: 项目
B32: 熟 料 | C32: 进厂 | D32: 自产
D33: 外购
C34: 出厂 | D34: 权属调拨
D35: 外发熟料
B36: 总销量
B37: 水泥销售量 | O37: 主 要 原 燃 材 料 动 态 | P37: 材料名称 | R37: 计划 | S37: 期初库存 | T37: 日进厂 | U37: 月累 进厂 | V37: 年累 进厂 | W37: 日消耗 | X37: 月累消耗 | Y37: 年累消耗 | Z37: 期末库存
B38: 其 中 | C38: 袋装 | P38: 安砂建福 | Q38: 无烟煤
C39: 散装 | Q39: 烟煤
B40: 商品熟料 | Q40: 石膏
...

Sheet yc
A1: 福建水泥股份有限公司生产日报表
A2: 计量单位：吨 | E2: 序时进度 | I2: =1/31 -> 0.032258065 | N2: 2025年11月报 | Z2: 表号:福泥运统字001
A3: 项目 | E3: 月计划 | F3: 期初库存 | G3: 日生产/进厂 | H3: 月累计 | I3: 年累计 | J3: 日消耗/出厂 | K3: 月累计 | L3: 年累计 | M3: 期末库存 | N3: 库容率% | O3: 项目 | R3: 台时产量（t/h，kwh/t） | U3: 运转率（%） | X3: 运行时间（h）
R4: 日 | S4: 月 | T4: 年 | U4: 日 | V4: 月 | W4: 年 | X4: 日 | Y4: 月 | Z4: 年
A5: 公司合计 | B5: 水泥生产/出厂 | E5: 732000 | I5: 6154866 | L5: 6150071.1 | M5: 267621.63 | N5: =M5/374000*100 -> 71.556587 | O5: 主机设备运行情况 | P5: 安砂建福 | Q5: 回转窑1 | T5: 259.93692 | W5: 64.662163 | Z5: 5183.319
B6: 其 中 | C6: P.O52.5 | I6: 276349.96 | L6: 262197.7 | M6: 32112.84 | Q6: 回转窑2 | T6: 240.28021 | W6: 35.494 | Z6: 2845.199
C7: P.P32.5 | I7: 0 | L7: 0 | M7: 0 | Q7: 水泥磨1 | T7: 131.9313 | W7: 31.005863 | Z7: 2485.43
C8: P.042.5R | I8: 525536.99 | L8: 507744.71 | M8: 41879.9 | Q8: 水泥磨2 | T8: 127.42427 | W8: 27.405813 | Z8: 2196.85
C9: P.042.5 | I9: 4135388.9 | L9: 4097478.8 | M9: 110865.71 | Q9: 水泥磨3 | T9: 271.31303 | W9: 34.875125 | Z9: 2795.59
C10: M32.5 | I10: 917527.17 | L10: 897228.72 | M10: 61206.942 | Q10: 水泥磨4 | T10: 268.85089 | W10: 34.481786 | Z10: 2764.06
C11: P.P32.5R | I11: 0 | L11: 0 | M11: 0 | Q11: 德化1#
B12: 熟 料 | C12: 进厂 | D12: 自产 | E12: 312000 | I12: 4942391.2 | L12: 5029106.4 | M12: 374437.15 | N12: =M12/439000*100 -> 85.293201 | Q12: 德化2# | T12: 0 | W12: 0 | Z12: 0
D13: 外购 | E13: 0 | I13: 0 | L13: 0 | M13: -2.0037305e-12 | N13: =(M12+M13)/315000*100 -> 118.86894 | P13: 永安建福 | Q13: 回转窑 | T13: 266.38218 | W13: 71.551023 | Z13: 5735.53
C14: 出厂 | D14: 权属调拨 | E14: 0 | I14: 964543.68 | L14: 1792944.1 | M14: 67362.78 | Q14: 水泥磨A1 | T14: 213.5005 | W14: 50.230788 | Z14: 4026.50
D15: 外发熟料 | E15: 0 | I15: 0 | L15: 114756.5 | Q15: 水泥磨D1 | T15: 61.284257 | W15: 50.754741 | Z15: 4068.50
B16: 总销量 | E16: 0 | I16: 0 | L16: 0 | Q16: 水泥磨D2 | T16: 62.916685 | W16: 52.348054 | Z16: 4196.22
B17: 水泥销售量 | E17: 810000 | I17: 0 | L17: 0 | P17: 金银湖水泥 | Q17: 回转窑 | T17: 0 | W17: 0 | Z17: 0
B18: 其 中 | C18: 袋装 | E18: 0 | I18: 0 | L18: 0 | Q18: 水泥磨1 | T18: 222.40493 | W18: 7.0101048 | Z18: 561.93
C19: 散装 | E19: 0 | I19: 0 | L19: 0 | P19: 顺昌炼石 | Q19: 回转窑1 | T19: 9.0909091e-06 | W19: 4.253992e-06 | Z19: 0.000341
B20: 商品熟料 | E20: 40000 | I20: 0 | L20: 0 | Q20: 回转窑2 | T20: 239.29986 | W20: 72.127375 | Z20: 5781.7303
A21: 安砂建福 | B21: 水泥生产/出厂 | E21: 312000 | I21: 2109438 | L21: 2066454 | M21: 83053.31 | N21: =M21/47000*100 -> 176.70917 | Q21: 水泥磨3 | T21: 275.68068 | W21: 36.124792 | Z21: 2895.7633
B22: 熟 料 | C22: 进厂 | D22: 自产 | E22: 97000 | I22: 2030981 | L22: 1891461.4 | M22: 189966.35 | N22: =(M22+M23)/(50000+150000)*100 -> 94.983176 | Q22: 水泥磨1 | T22: 102.26006 | W22: 45.378729 | Z22: 3637.5589
D23: 外购 | I23: 0 | L23: 0 | M23: 0 | Q23: 水泥磨2 | T23: 79.127604 | W23: 32.495707 | Z23: 2604.8558
C24: 出厂 | D24: 权属调拨 | I24: 0 | L24: 279826.53 | M24: 0 | P24: 福州炼石 | Q24: 水泥磨1 | T24: 86.49 | W24: 52.319361 | Z24: 4193.92
D25: 外发熟料 | I25: 0 | L25: 79320.85 | Q25: 水泥磨2 | T25: 187.67 | W25: 50.181886 | Z25: 4022.58
B26: 总销量 | I26: 0 | L26: 0 | P26: 宁德建福 | Q26: 水泥磨2 | T26: 0 | W26: 0 | Z26: 0
B27: 水泥销售量 | E27: 240000 | I27: 0 | L27: 0 | O27: 余热发电 | P27: 永安建福 | T27: 25.375402 | W27: 68.374251 | Z27: 5480.88
B28: 其 中 | C28: 袋装 | I28: 0 | L28: 0 | P28: 安砂建福1# | T28: 25.943432 | W28: 64.371881 | Z28: 5160.05
C29: 散装 | I29: 0 | L29: 0 | P29: 安砂建福2# | T29: 29.934238 | W29: 34.98231 | Z29: 2804.182
B30: 商品熟料 | I30: 0 | L30: 0 | P30: 金银湖水泥 | T30: 0 | W30: 0 | Z30: 0
A31: 永安建福 | B31: 水泥生产/出厂 | E31: 180000 | I31: 1373007 | L31: 1356048.1 | M31: 65429.37 | N31: =M31/75000*100 -> 87.23916
B32: 熟 料 | C32: 进厂 | D32: 自产 | E32: 97000 | I32: 1527843 | L32: 1021478 | M32: 60437.506 | N32: =(M32+M33)/50000*100 -> 120.87501 | P32: 顺昌炼石1# | T32: 0 | W32: 4.1167665e-11 | Z32: 3.3e-09
D33: 外购 | I33: 0 | L33: 0 | M33: 0 | P33: 顺昌炼石2# | T33: 19.77 | W33: 63.121507 | Z33: 5059.82
C34: 出厂 | D34: 权属调拨 | I34: 0 | L34: 467202.93 | M34: 0
D35: 外发熟料 | I35: 0 | L35: 0
B36: 总销量 | I36: 0 | L36: 0 | P36: 材料名称 | R36: 计划 | S36: 期初库存 | T36: 日进厂 | U36: 月累 进厂 | V36: 年累 进厂 | W36: 日消耗 | X36: 月累消耗 | Y36: 年累消耗 | Z36: 期末库存
B37: 水泥销售量 | E37: 200000 | I37: 0 | L37: 0 | O37: 主 要 原 燃 材 料 动 态 | P37: 安砂建福 | Q37: 无烟煤 | V37: 0 | Y37: 0
B38: 其 中 | C38: 袋装 | I38: 0 | L38: 0 | Q38: 烟煤 | V38: 259139.72 | Y38: 256107
C39: 散装 | I39: 0 | L39: 0 | Q39: 石膏 | V39: 78813.599 | Y39: 78759
B40: 商品熟料 | I40: 0 | L40: 0 | Q40: 铁粉 | V40: 0 | Y40: 0
...

Sheet kb
A1: 福建水泥股份有限公司日报表
A2: 计量单位：吨 | E2: 序时进度 | I2: =0/0 -> #DIV/0! | N2: 42005 | Z2: 表号:福泥运统字001
A3: 项目 | E3: 月计划 | F3: 期初库存 | G3: 日生产/进厂 | H3: 月累计 | I3: 年累计 | J3: 日消耗/出厂 | K3: 月累计 | L3: 年累计 | M3: 期末库存 | N3: 库容率% | O3: 项目 | R3: 台时产量（t/h，kwh/t） | U3: 运转率（%） | X3: 运行时间（h）
R4: 日 | S4: 月 | T4: 年 | U4: 日 | V4: 月 | W4: 年 | X4: 日 | Y4: 月 | Z4: 年
A5: 公司合计 | B5: 水泥生产/出厂 | E5: =E21+E31+E41+E51+E61+E71+E78+E85 -> 700000 | F5: =F21+F31+F41+F51+F61+F71+F78+F85 -> 0 | G5: =G21+G31+G41+G51+G61+G71+G78+G85 -> 0 | H5: =G5+'r'!H5 -> 0 | I5: =H5+yc!I5 -> 6154866 | J5: =J21+J31+J41+J51+J61+J71+J78+J85 -> 0 | K5: =J5+'r'!K5 -> 0 | L5: =K5+yc!L5 -> 6150071.1 | M5: =M21+M31+M41+M51+M61+M71+M78+M85 -> 0 | N5: =M5/374000*100 -> 0 | O5: 主机设备运行情况 | P5: 安砂 | Q5: 回转窑
B6: 其 中 | C6: P.O52.5 | H6: =G6+'r'!H6 -> 0 | I6: =H6+yc!I6 -> 276349.96 | K6: =J6+'r'!K6 -> 0 | L6: =K6+yc!L6 -> 262197.7 | Q6: 水泥磨1
C7: PII42.5 | H7: =G7+'r'!H7 -> 0 | I7: =H7+yc!I7 -> 0 | K7: =J7+'r'!K7 -> 0 | L7: =K7+yc!L7 -> 0 | Q7: 水泥磨2
C8: P.042.5R | H8: =G8+'r'!H8 -> 0 | I8: =H8+yc!I8 -> 525536.99 | K8: =J8+'r'!K8 -> 0 | L8: =K8+yc!L8 -> 507744.71 | Q8: 回转窑
C9: P.042.5 | H9: =G9+'r'!H9 -> 0 | I9: =H9+yc!I9 -> 4135388.9 | K9: =J9+'r'!K9 -> 0 | L9: =K9+yc!L9 -> 4097478.8 | P9: 曹远 | Q9: 水泥磨A1
C10: P.C32.5R | H10: =G10+'r'!H10 -> 0 | I10: =H10+yc!I10 -> 917527.17 | K10: =J10+'r'!K10 -> 0 | L10: =K10+yc!L10 -> 897228.72 | Q10: 水泥磨D1
C11: P.C32.5 | H11: =G11+'r'!H11 -> 0 | I11: =H11+yc!I11 -> 0 | K11: =J11+'r'!K11 -> 0 | L11: =K11+yc!L11 -> 0 | Q11: 水泥磨D2
B12: 熟 料 | C12: 进厂 | D12: 自产 | E12: =E22+E32+E42+E52+E62 -> 560000 | F12: =F22+F32+F42+F52+F62+F72+F79+F86 -> 0 | G12: =G22+G32+G42+G52+G62 -> 0 | H12: =G12+'r'!H12 -> 0 | I12: =H12+yc!I12 -> 4942391.2 | J12: =J22+J32+J42+J52+J62+J72+J79+J86 -> 0 | K12: =J12+'r'!K12 -> 0 | L12: =K12+yc!L12 -> 5029106.4 | M12: =M28+M38+M48+M58+M68+M78+M85+M92 -> 0 | N12: =M12/439000*100 -> 0 | P12: 德化 | Q12: 回转窑
D13: 外购 | E13: =E23+E33+E43+E53+E63+E73+E80+E87 -> 0 | G13: =G23+G33+G43+G53+G63+G73+G80+G87 -> 0 | H13: =G13+'r'!H13 -> 0 | I13: =H13+yc!I13 -> 0 | K13: =J13+'r'!K13 -> 0 | L13: =K13+yc!L13 -> 0 | Q13: 水泥磨1
C14: 出厂 | D14: 权属调拨 | E14: =E24+E34+E44+E54+E64 -> 0 | G14: =G24+G34+G44+G54+G64 -> 0 | H14: =G14+'r'!H14 -> 0 | I14: =H14+yc!I14 -> 964543.68 | J14: =J24+J34+J44+J54+J64 -> 0 | K14: =J14+'r'!K14 -> 0 | L14: =K14+yc!L14 -> 1792944.1 | Q14: 水泥磨2
D15: 外发熟料 | E15: =E25+E35+E45+E55+E65 -> 0 | G15: =G25+G35+G45+G55+G65 -> 0 | H15: =G15+'r'!H15 -> 0 | I15: =H15+yc!I15 -> 0 | J15: =J25+J35+J45+J55+J65 -> 0 | K15: =J15+'r'!K15 -> 0 | L15: =K15+yc!L15 -> 114756.5 | P15: 大湖 | Q15: 回转窑
B16: 总销量 | E16: =E26+E36+E46+E56+E66+E74+E81+E88 -> 700000 | G16: =G26+G36+G46+G56+G66+G74+G81+G88 -> 0 | H16: =G16+'r'!H16 -> 0 | I16: =H16+yc!I16 -> 0 | J16: =J26+J36+J46+J56+J66+J74+J81+J88 -> 0 | K16: =J16+'r'!K16 -> 0 | L16: =K16+yc!L16 -> 0 | Q16: 水泥磨1
B17: 水泥销售量 | E17: =E27+E37+E47+E57+E67+E75+E82+E89 -> 700000 | G17: =G27+G37+G47+G57+G67+G75+G82+G89 -> 0 | H17: =G17+'r'!H17 -> 0 | I17: =H17+yc!I17 -> 0 | J17: =J27+J37+J47+J57+J67+J75+J82+J89 -> 0 | K17: =J17+'r'!K17 -> 0 | L17: =K17+yc!L17 -> 0 | P17: 顺昌 | Q17: 回转窑4k
B18: 其 中 | C18: 袋装 | E18: =E28+E38+E48+E58+E68+E76+E83+E90 -> 318000 | G18: =G28+G38+G48+G58+G68+G76+G83+G90 -> 0 | H18: =G18+'r'!H18 -> 0 | I18: =H18+yc!I18 -> 0 | J18: =J28+J38+J48+J58+J68+J76+J83+J90 -> 0 | K18: =J18+'r'!K18 -> 0 | L18: =K18+yc!L18 -> 0 | Q18: 回转窑5k
C19: 散装 | E19: =E29+E39+E49+E59+E69+E77+E84+E91 -> 382000 | G19: =G29+G39+G49+G59+G69+G77+G84+G91 -> 0 | H19: =G19+'r'!H19 -> 0 | I19: =H19+yc!I19 -> 0 | J19: =J29+J39+J49+J59+J69+J77+J84+J91 -> 0 | K19: =J19+'r'!K19 -> 0 | L19: =K19+yc!L19 -> 0 | Q19: 回转窑8k
B20: 商品熟料 | E20: =E30+E40+E50+E60+E70 -> 0 | G20: =G30+G40+G50+G60+G70 -> 0 | H20: =G20+'r'!H20 -> 0 | I20: =H20+yc!I20 -> 0 | J20: =J30+J40+J50+J60+J70 -> 0 | K20: =J20+'r'!K20 -> 0 | L20: =K20+yc!L20 -> 0 | Q20: 水泥磨1
A21: 安砂 | B21: 水泥生产/出厂 | E21: 123000 | H21: =G21+'r'!H21 -> 0 | I21: =H21+yc!I21 -> 2109438 | K21: =J21+'r'!K21 -> 0 | L21: =K21+yc!L21 -> 2066454 | N21: =M21/47000*100 -> 0 | Q21: 水泥磨2
B22: 熟 料 | C22: 进厂 | D22: 自产 | E22: 131000 | H22: =G22+'r'!H22 -> 0 | I22: =H22+yc!I22 -> 2030981 | K22: =J22+'r'!K22 -> 0 | L22: =K22+yc!L22 -> 1891461.4 | N22: =M22/55000*100 -> 0 | P22: 闽侯 | Q22: 水泥磨1
D23: 外购 | H23: =G23+'r'!H23 -> 0 | I23: =H23+yc!I23 -> 0 | K23: =J23+'r'!K23 -> 0 | L23: =K23+yc!L23 -> 0 | Q23: 水泥磨2
C24: 出厂 | D24: 权属调拨 | H24: =G24+'r'!H24 -> 0 | I24: =H24+yc!I24 -> 0 | K24: =J24+'r'!K24 -> 0 | L24: =K24+yc!L24 -> 279826.53 | P24: 漳州 | Q24: 水泥磨1
D25: 外发熟料 | H25: =G25+'r'!H25 -> 0 | I25: =H25+yc!I25 -> 0 | K25: =J25+'r'!K25 -> 0 | L25: =K25+yc!L25 -> 79320.85 | P25: 宁德 | Q25: 水泥磨2
B26: 总销量 | E26: =E27+E30 -> 122000 | H26: =G26+'r'!H26 -> 0 | I26: =H26+yc!I26 -> 0 | J26: =J27+J30 -> 0 | K26: =J26+'r'!K26 -> 0 | L26: =K26+yc!L26 -> 0 | O26: 余热发电 | P26: 曹远
B27: 水泥销售量 | E27: =SUM(E28:E29) -> 122000 | H27: =G27+'r'!H27 -> 0 | I27: =H27+yc!I27 -> 0 | J27: =SUM(J28:J29) -> 0 | K27: =J27+'r'!K27 -> 0 | L27: =K27+yc!L27 -> 0 | P27: 安砂
B28: 其 中 | C28: 袋装 | E28: 64000 | H28: =G28+'r'!H28 -> 0 | I28: =H28+yc!I28 -> 0 | K28: =J28+'r'!K28 -> 0 | L28: =K28+yc!L28 -> 0 | P28: 大湖
C29: 散装 | E29: 58000 | H29: =G29+'r'!H29 -> 0 | I29: =H29+yc!I29 -> 0 | K29: =J29+'r'!K29 -> 0 | L29: =K29+yc!L29 -> 0 | P29: 德化
B30: 商品熟料 | H30: =G30+'r'!H30 -> 0 | I30: =H30+yc!I30 -> 0 | K30: =J30+'r'!K30 -> 0 | L30: =K30+yc!L30 -> 0 | P30: 顺昌1
A31: 曹远 | B31: 水泥生产/出厂 | E31: 118000 | H31: =G31+'r'!H31 -> 0 | I31: =H31+yc!I31 -> 1373007 | K31: =J31+'r'!K31 -> 0 | L31: =K31+yc!L31 -> 1356048.1 | N31: =M31/75000*100 -> 0 | P31: 顺昌2
B32: 熟 料 | C32: 进厂 | D32: 自产 | E32: 131000 | H32: =G32+'r'!H32 -> 0 | I32: =H32+yc!I32 -> 1527843 | K32: =J32+'r'!K32 -> 0 | L32: =K32+yc!L32 -> 1021478 | N32: =M32/65000*100 -> 0 | O32: 监控指标 | P32: 项目 | R32: 安砂 | S32: 曹远 | T32: 德化 | U32: 大湖 | V32: 顺昌 | W32: 闽侯 | X32: 漳州 | Y32: 宁德
D33: 外购 | H33: =G33+'r'!H33 -> 0 | I33: =H33+yc!I33 -> 0 | K33: =J33+'r'!K33 -> 0 | L33: =K33+yc!L33 -> 0 | P33: 原料耗 | Q33: 年度累计
C34: 出厂 | D34: 权属调拨 | H34: =G34+'r'!H34 -> 0 | I34: =H34+yc!I34 -> 0 | K34: =J34+'r'!K34 -> 0 | L34: =K34+yc!L34 -> 467202.93 | P34: 生料耗 | Q34: 年度累计
D35: 外发熟料 | H35: =G35+'r'!H35 -> 0 | I35: =H35+yc!I35 -> 0 | K35: =J35+'r'!K35 -> 0 | L35: =K35+yc!L35 -> 0 | P35: 熟料耗 | Q35: 年度累计
B36: 总销量 | E36: =E37+E40 -> 118000 | H36: =G36+'r'!H36 -> 0 | I36: =H36+yc!I36 -> 0 | J36: =J37+J40 -> 0 | L36: =K36+yc!L36 -> 0 | P36: 煤损耗 | Q36: 年度累计
B37: 水泥销售量 | E37: =SUM(E38:E39) -> 118000 | H37: =G37+'r'!H37 -> 0 | I37: =H37+yc!I37 -> 0 | J37: =SUM(J38:J39) -> 0 | K37: =J37+'r'!K37 -> 0 | L37: =K37+yc!L37 -> 0 | O37: 主 要 原 燃 材 料 动 态 | P37: 水泥耗 | Q37: 年度累计
B38: 其 中 | C38: 袋装 | E38: 76000 | H38: =G38+'r'!H38 -> 0 | I38: =H38+yc!I38 -> 0 | K38: =J38+'r'!K38 -> 0 | L38: =K38+yc!L38 -> 0 | P38: 材料名称 | R38: 计划 | S38: 期初库存 | T38: 日进厂 | U38: 月累 进厂 | V38: 年累 进厂 | W38: 日消耗 | X38: 月累消耗 | Y38: 年累消耗 | Z38: 期末库存
C39: 散装 | E39: 42000 | H39: =G39+'r'!H39 -> 0 | I39: =H39+yc!I39 -> 0 | K39: =J39+'r'!K39 -> 0 | L39: =K39+yc!L39 -> 0 | P39: 安砂 | Q39: 无烟煤 | R39: 22500 | S39: =[1]月报!$S$17 -> 9938.78 | T39: =[1]月报!$T$17 -> 0 | V39: =U39+yc!V35 -> 0 | W39: =[1]月报!$W$17 -> 0 | Y39: =X39+yc!Y35 -> 0 | Z39: =Y39+#REF! -> #REF!
B40: 商品熟料 | H40: =G40+'r'!H40 -> 0 | I40: =H40+yc!I40 -> 0 | K40: =J40+'r'!K40 -> 0 | L40: =K40+yc!L40 -> 0 | V40: =U40+yc!V36 -> #VALUE! | Y40: =X40+yc!Y36 -> #VALUE!
...

Sheet 1
A1: 福建水泥股份有限公司生产日报表
A2: 计量单位：吨 | E2: 序时进度 | I2: =1/31 -> 0.032258065 | N2: 45992 | Z2: 表号:福泥运统字001
A3: 项目 | E3: 月计划 | F3: 期初库存 | G3: 日生产/进厂 | H3: 月累计 | I3: 年累计 | J3: 日消耗/出厂 | K3: 月累计 | L3: 年累计 | M3: 期末库存 | N3: 库容率% | O3: 项目 | R3: 台时产量（t/h，kwh/t） | U3: 运转率（%） | X3: 运行时间（h）
R4: 日 | S4: 月 | T4: 年 | U4: 日 | V4: 月 | W4: 年 | X4: 日 | Y4: 月 | Z4: 年
A5: 公司合计 | B5: 水泥生产/出厂 | E5: =E21+E31+E41+E51+E61+E68+E79 -> 650000 | F5: =F21+F31+F41+F51+F61+F68+F79 -> 262736.85 | G5: =G21+G31+G41+G51+G61+G68+G79 -> 16526.84 | H5: =G5+'r'!H5 -> 16526.84 | I5: =H5+yc!I5 -> 6171392.9 | J5: =J21+J31+J41+J51+J61+J68+J79 -> 22586.48 | K5: =J5+'r'!K5 -> 22586.48 | L5: =K5+yc!L5 -> 6172657.6 | M5: =M21+M31+M41+M51+M61+M68+M79 -> 261561.99 | N5: =M5/374000*100 -> 69.936362 | O5: 主机设备运行情况 | P5: 安砂建福 | Q5: 回转窑1 | R5: ='[10]1'!$W$101 -> 273.58333 | S5: ='[10]1'!$X$101 -> 273.58333 | T5: ='[10]1'!$Y$101 -> 259.99982 | U5: ='[10]1'!$T$101 -> 100 | V5: ='[10]1'!$U$101 -> 100 | W5: ='[10]1'!$V$101 -> 64.767649 | X5: ='[10]1'!$Q$101 -> 24 | Y5: ='[10]1'!$R$101 -> 24 | Z5: ='[10]1'!$S$101 -> 5207.319
B6: 其 中 | C6: P.O52.5 | F6: ='[10]1'!$D$23+'[11]1'!$D$17+'[12]1'!$D$17+'[13]1'!$D$25+'[14]1'!$D$8+'[14]1'!$D$15+'[15]1'!$D$7 -> 32112.84 | G6: ='[10]1'!$E$23+'[11]1'!$E$17+'[12]1'!$E$17+'[13]1'!$E$25+'[14]1'!$E$8+'[14]1'!$E$15+'[15]1'!$E$7 -> 0 | H6: =G6+'r'!H6 -> 0 | I6: =H6+yc!I6 -> 276349.96 | J6: ='[10]1'!$I$23+'[11]1'!$I$17+'[12]1'!$I$17+'[13]1'!$I$25+'[14]1'!$E$23+'[14]1'!$E$30+'[15]1'!$H$7 -> 867.58 | K6: =J6+'r'!K6 -> 867.58 | L6: =K6+yc!L6 -> 263065.28 | M6: ='[10]1'!$L$23+'[11]1'!$L$17+'[12]1'!$L$17+'[13]1'!$L$25+'[14]1'!$H$23+'[14]1'!$H$30+'[15]1'!$K$7 -> 31245.26 | Q6: 回转窑2 | R6: ='[10]1'!$W$102 -> 0 | S6: ='[10]1'!$X$102 -> 0 | T6: ='[10]1'!$Y$102 -> 240.28021 | U6: ='[10]1'!$T$102 -> 0 | V6: ='[10]1'!$U$102 -> 0 | W6: ='[10]1'!$V$102 -> 35.388047 | X6: ='[10]1'!$Q$102 -> 0 | Y6: ='[10]1'!$R$102 -> 0 | Z6: ='[10]1'!$S$102 -> 2845.199
C7: M22.5 | F7: ='[12]1'!$D$22 -> 0 | G7: ='[12]1'!$E$22 -> 0 | H7: =G7+'r'!H7 -> 0 | I7: =H7+yc!I7 -> 0 | J7: ='[12]1'!$I$22 -> 0 | K7: =J7+'r'!K7 -> 0 | L7: =K7+yc!L7 -> 0 | M7: ='[12]1'!$L$22 -> 0 | Q7: 水泥磨1 | R7: ='[10]1'!$W$107 -> 128 | S7: ='[10]1'!$X$107 -> 128 | T7: ='[10]1'!$Y$107 -> 131.91554 | U7: ='[10]1'!$T$107 -> 41.666667 | V7: ='[10]1'!$U$107 -> 41.666667 | W7: ='[10]1'!$V$107 -> 31.037687 | X7: ='[10]1'!$Q$107 -> 10 | Y7: ='[10]1'!$R$107 -> 10 | Z7: ='[10]1'!$S$107 -> 2495.43
C8: P.042.5R | F8: ='[10]1'!$D$27+'[11]1'!$D$18+'[13]1'!$D$26+'[14]1'!$D$10+'[14]1'!$D$17+'[15]1'!$D$9 -> 41879.9 | G8: ='[10]1'!$E$27+'[11]1'!$E$18+'[13]1'!$E$26+'[14]1'!$E$10+'[14]1'!$E$17+'[15]1'!$E$9 -> 1999 | H8: =G8+'r'!H8 -> 1999 | I8: =H8+yc!I8 -> 527535.99 | J8: ='[10]1'!$I$27+'[11]1'!$I$18+'[13]1'!$I$26+'[14]1'!$E$25+'[14]1'!$E$32+'[15]1'!$H$9 -> 2353.67 | K8: =J8+'r'!K8 -> 2353.67 | L8: =K8+yc!L8 -> 510098.38 | M8: ='[10]1'!$L$27+'[11]1'!$L$18+'[13]1'!$L$26+'[14]1'!$H$25+'[14]1'!$H$32+'[15]1'!$K$9 -> 41525.23 | Q8: 水泥磨2 | R8: ='[10]1'!$W$108 -> 129.4 | S8: ='[10]1'!$X$108 -> 129.4 | T8: ='[10]1'!$Y$108 -> 127.43322 | U8: ='[10]1'!$T$108 -> 41.666667 | V8: ='[10]1'!$U$108 -> 41.666667 | W8: ='[10]1'!$V$108 -> 27.448383 | X8: ='[10]1'!$Q$108 -> 10 | Y8: ='[10]1'!$R$108 -> 10 | Z8: ='[10]1'!$S$108 -> 2206.85
C9: P.042.5 | F9: ='[10]1'!$D$24+'[11]1'!$D$19+'[12]1'!$D$20+'[13]1'!$D$27+'[14]1'!$D$11+'[14]1'!$D$18+'[15]1'!$D$10 -> 110865.71 | G9: ='[10]1'!$E$24+'[11]1'!$E$19+'[12]1'!$E$20+'[13]1'!$E$27+'[14]1'!$E$11+'[14]1'!$E$18+'[15]1'!$E$10 -> 11619 | H9: =G9+'r'!H9 -> 11619 | I9: =H9+yc!I9 -> 4147007.9 | J9: ='[10]1'!$I$24+'[11]1'!$I$19+'[12]1'!$I$20+'[13]1'!$I$27+'[14]1'!$E$26+'[14]1'!$E$33+'[15]1'!$H$10 -> 14642.03 | K9: =J9+'r'!K9 -> 14642.03 | L9: =K9+yc!L9 -> 4112120.8 | M9: ='[10]1'!$L$24+'[11]1'!$L$19+'[12]1'!$L$20+'[13]1'!$L$27+'[14]1'!$H$26+'[14]1'!$H$33+'[15]1'!$K$10 -> 107842.68 | Q9: 水泥磨3 | R9: ='[10]1'!$W$109 -> 257.02775 | S9: ='[10]1'!$X$109 -> 257.02775 | T9: ='[10]1'!$Y$109 -> 271.25618 | U9: ='[10]1'!$T$109 -> 46.541667 | V9: ='[10]1'!$U$109 -> 46.541667 | W9: ='[10]1'!$V$109 -> 34.90995 | X9: ='[10]1'!$Q$109 -> 11.17 | Y9: ='[10]1'!$R$109 -> 11.17 | Z9: ='[10]1'!$S$109 -> 2806.76
C10: M32.5 | F10: ='[10]1'!$D$25+'[11]1'!$D$20+'[12]1'!$D$21+'[13]1'!$D$28+'[14]1'!$D$12+'[14]1'!$D$19+'[15]1'!$D$11 -> 61206.942 | G10: ='[10]1'!$E$25+'[11]1'!$E$20+'[12]1'!$E$21+'[13]1'!$E$28+'[14]1'!$E$12+'[14]1'!$E$19+'[15]1'!$E$11 -> 1220 | H10: =G10+'r'!H10 -> 1220 | I10: =H10+yc!I10 -> 918747.17 | J10: ='[10]1'!$I$25+'[11]1'!$I$20+'[12]1'!$I$21+'[13]1'!$I$28+'[14]1'!$E$27+'[14]1'!$E$34+'[15]1'!$H$11 -> 3341 | K10: =J10+'r'!K10 -> 3341 | L10: =K10+yc!L10 -> 900569.72 | M10: ='[10]1'!$L$25+'[11]1'!$L$20+'[12]1'!$L$21+'[13]1'!$L$28+'[14]1'!$H$27+'[14]1'!$H$34+'[15]1'!$K$11 -> 59085.942 | Q10: 水泥磨4 | R10: ='[10]1'!$W$110 -> 0 | S10: ='[10]1'!$X$110 -> 0 | T10: ='[10]1'!$Y$110 -> 268.85089 | U10: ='[10]1'!$T$110 -> 0 | V10: ='[10]1'!$U$110 -> 0 | W10: ='[10]1'!$V$110 -> 34.378856 | X10: ='[10]1'!$Q$110 -> 0 | Y10: ='[10]1'!$R$110 -> 0 | Z10: ='[10]1'!$S$110 -> 2764.06
C11: P.P32.5R | F11: ='[10]1'!$D$26+'[11]1'!$D$21+'[12]1'!$D$19+'[13]1'!$D$29+'[14]1'!$D$13+'[14]1'!$D$20 -> 0 | G11: ='[10]1'!$E$26+'[11]1'!$E$21+'[12]1'!$E$19+'[13]1'!$E$29+'[14]1'!$E$13+'[14]1'!$E$20 -> 0 | H11: =G11+'r'!H11 -> 0 | I11: =H11+yc!I11 -> 0 | J11: ='[10]1'!$I$26+'[11]1'!$I$21+'[12]1'!$I$19+'[13]1'!$I$29+'[14]1'!$E$28+'[14]1'!$E$35 -> 0 | K11: =J11+'r'!K11 -> 0 | L11: =K11+yc!L11 -> 0 | M11: ='[10]1'!$L$26+'[11]1'!$L$21+'[12]1'!$L$19+'[13]1'!$L$29+'[14]1'!$H$28+'[14]1'!$H$35 -> 0 | Q11: 德化1#
B12: 熟 料 | C12: 进厂 | D12: 自产 | E12: =E22+E32+E42+E52 -> 538000 | F12: =F22+F32+F42+F52+F62+F69 -> 374372.6 | G12: =G22+G32+G42+G52 -> 8314 | H12: =G12+'r'!H12 -> 8314 | I12: =H12+yc!I12 -> 4950705.2 | J12: =J22+J32+J42+J52+J62+J69 -> 14841.468 | K12: =J12+'r'!K12 -> 14841.468 | L12: =K12+yc!L12 -> 5043947.8 | M12: =M22+M32+M42+M52+M62+M69 -> 367178.24 | N12: =M12/439000*100 -> 83.63969 | Q12: 德化2# | R12: ='[16]1'!$W$40 -> 0 | S12: ='[16]1'!$X$40 -> 0 | T12: ='[16]1'!$Y$40 -> 0 | U12: ='[16]1'!$T$40 -> 0 | V12: ='[16]1'!$U$40 -> 0 | W12: ='[16]1'!$V$40 -> 0 | X12: ='[16]1'!$Q$40 -> 0 | Y12: ='[16]1'!$R$40 -> 0 | Z12: ='[16]1'!$S$40 -> 0
D13: 外购 | E13: =E23+E33+E43+E53+E63+E70 -> 0 | F13: =F23+F33+F43+F53+F63+F70 -> -2.0037305e-12 | G13: =G23+G33+G43+G53+G63+G70 -> 0 | H13: =G13+'r'!H13 -> 0 | I13: =H13+yc!I13 -> 0 | J13: =J23+J33+J43+J53+J63+J70 -> 0 | K13: =J13+'r'!K13 -> 0 | L13: =K13+yc!L13 -> 0 | M13: =M23+M33+M43+M53+M63+M70 -> -2.0037305e-12 | N13: =(M12+M13)/(315000+80000+150000)*100 -> 67.372154 | P13: 永安建福 | Q13: 回转窑 | R13: ='[11]1'!$W$68 -> 277.46032 | S13: ='[11]1'!$X$68 -> 277.46032 | T13: ='[11]1'!$Y$68 -> 266.39434 | U13: ='[11]1'!$T$68 -> 26.25 | V13: ='[11]1'!$U$68 -> 26.25 | W13: ='[11]1'!$V$68 -> 71.415796 | X13: ='[11]1'!$Q$68 -> 6.30 | Y13: ='[11]1'!$R$68 -> 6.30 | Z13: ='[11]1'!$S$68 -> 5741.83
C14: 出厂 | D14: 权属调拨 | E14: =E24+E34+E44+E54 -> 0 | F14: =F24+F34+F44+F54 -> 0 | G14: =G24+G34+G44+G54+G62 -> 0 | H14: =G14+'r'!H14 -> 0 | I14: =H14+yc!I14 -> 964543.68 | J14: =J24+J34+J44+J54+J62 -> 5189.246 | K14: =J14+'r'!K14 -> 5189.246 | L14: =K14+yc!L14 -> 1798133.4 | M14: =M24+M34+M44+M54 -> 67564.78 | Q14: 水泥磨A1 | R14: ='[11]1'!$W$71 -> 200.375 | S14: ='[11]1'!$X$71 -> 200.375 | T14: ='[11]1'!$Y$71 -> 213.47447 | U14: ='[11]1'!$T$71 -> 33.333333 | V14: ='[11]1'!$U$71 -> 33.333333 | W14: ='[11]1'!$V$71 -> 50.180348 | X14: ='[11]1'!$Q$71 -> 8.00 | Y14: ='[11]1'!$R$71 -> 8.00 | Z14: ='[11]1'!$S$71 -> 4034.50
D15: 外发熟料 | E15: =E25+E35+E45+E55 -> 0 | F15: =F25+F35+F45+F55 -> 0 | G15: =G25+G35+G45+G55 -> 0 | H15: =G15+'r'!H15 -> 0 | I15: =H15+yc!I15 -> 0 | J15: =J25+J35+J45+J55 -> 473.78 | K15: =J15+'r'!K15 -> 473.78 | L15: =K15+yc!L15 -> 115230.28 | Q15: 水泥磨D1 | R15: ='[11]1'!$W$72 -> 62.375 | S15: ='[11]1'!$X$72 -> 62.375 | T15: ='[11]1'!$Y$72 -> 61.286398 | U15: ='[11]1'!$T$72 -> 33.333333 | V15: ='[11]1'!$U$72 -> 33.333333 | W15: ='[11]1'!$V$72 -> 50.702736 | X15: ='[11]1'!$Q$72 -> 8.00 | Y15: ='[11]1'!$R$72 -> 8.00 | Z15: ='[11]1'!$S$72 -> 4076.50
